INFO 2025-10-26 12:46:40,590 utils 16424 20016 Created role: CUSTOMER
INFO 2025-10-26 12:46:40,593 utils 16424 20016 Created role: BANK_ADMIN
INFO 2025-10-26 12:46:40,594 utils 16424 20016 Created role: AUDITOR
INFO 2025-10-26 12:46:57,899 autoreload 11824 18492 Watching for file changes with StatReloader
INFO 2025-10-26 12:50:26,780 autoreload 11824 18492 C:\Users\Sakshi kumari\Documents\hclhackathon2025\smartbank\smartbank\settings.py changed, reloading.
INFO 2025-10-26 12:50:28,788 autoreload 12016 22672 Watching for file changes with StatReloader
INFO 2025-10-26 12:50:35,752 autoreload 12016 22672 C:\Users\Sakshi kumari\Documents\hclhackathon2025\smartbank\smartbank\settings.py changed, reloading.
INFO 2025-10-26 12:50:40,795 autoreload 18676 22124 Watching for file changes with StatReloader
INFO 2025-10-26 12:51:14,234 autoreload 18676 22124 C:\Users\Sakshi kumari\Documents\hclhackathon2025\smartbank\smartbank\settings.py changed, reloading.
INFO 2025-10-26 12:51:15,919 autoreload 22512 22288 Watching for file changes with StatReloader
INFO 2025-10-26 12:53:03,236 autoreload 22964 11604 Watching for file changes with StatReloader
INFO 2025-10-26 12:53:18,803 autoreload 22964 11604 C:\Users\Sakshi kumari\Documents\hclhackathon2025\smartbank\smartbank\settings.py changed, reloading.
INFO 2025-10-26 12:53:20,496 autoreload 2544 15628 Watching for file changes with StatReloader
INFO 2025-10-26 12:54:28,077 autoreload 2544 15628 C:\Users\Sakshi kumari\Documents\hclhackathon2025\smartbank\smartbank\settings.py changed, reloading.
INFO 2025-10-26 12:54:29,477 autoreload 22840 21856 Watching for file changes with StatReloader
INFO 2025-10-26 12:55:57,815 autoreload 22840 21856 C:\Users\Sakshi kumari\Documents\hclhackathon2025\smartbank\smartbank\settings.py changed, reloading.
INFO 2025-10-26 12:56:00,345 autoreload 22200 1832 Watching for file changes with StatReloader
INFO 2025-10-26 12:56:07,086 autoreload 22200 1832 C:\Users\Sakshi kumari\Documents\hclhackathon2025\smartbank\smartbank\settings.py changed, reloading.
INFO 2025-10-26 12:56:08,569 autoreload 22932 21812 Watching for file changes with StatReloader
INFO 2025-10-26 12:56:18,217 autoreload 22932 21812 C:\Users\Sakshi kumari\Documents\hclhackathon2025\smartbank\smartbank\settings.py changed, reloading.
INFO 2025-10-26 12:56:20,187 autoreload 22928 23268 Watching for file changes with StatReloader
INFO 2025-10-26 12:56:24,926 autoreload 22928 23268 C:\Users\Sakshi kumari\Documents\hclhackathon2025\smartbank\smartbank\urls.py changed, reloading.
INFO 2025-10-26 12:56:27,304 autoreload 22616 1832 Watching for file changes with StatReloader
INFO 2025-10-26 12:56:33,248 autoreload 22616 1832 C:\Users\Sakshi kumari\Documents\hclhackathon2025\smartbank\registration\views.py changed, reloading.
INFO 2025-10-26 12:56:35,475 autoreload 15296 22896 Watching for file changes with StatReloader
INFO 2025-10-26 12:56:40,788 autoreload 15296 22896 C:\Users\Sakshi kumari\Documents\hclhackathon2025\smartbank\registration\views.py changed, reloading.
INFO 2025-10-26 12:56:43,086 autoreload 7636 9912 Watching for file changes with StatReloader
INFO 2025-10-26 12:56:47,257 autoreload 7636 9912 C:\Users\Sakshi kumari\Documents\hclhackathon2025\smartbank\registration\views.py changed, reloading.
INFO 2025-10-26 12:56:49,495 autoreload 18828 23492 Watching for file changes with StatReloader
INFO 2025-10-26 12:56:56,600 autoreload 18828 23492 C:\Users\Sakshi kumari\Documents\hclhackathon2025\smartbank\registration\views.py changed, reloading.
INFO 2025-10-26 12:56:59,046 autoreload 11136 22220 Watching for file changes with StatReloader
INFO 2025-10-26 12:57:32,591 autoreload 11136 22220 C:\Users\Sakshi kumari\Documents\hclhackathon2025\smartbank\registration\views.py changed, reloading.
INFO 2025-10-26 12:57:34,682 autoreload 2888 14424 Watching for file changes with StatReloader
WARNING 2025-10-26 12:58:13,236 log 2888 23448 Bad Request: /api/auth/register/
WARNING 2025-10-26 12:58:17,392 log 2888 23448 Bad Request: /api/auth/register/
INFO 2025-10-26 12:59:26,390 autoreload 7636 21516 Watching for file changes with StatReloader
ERROR 2025-10-26 13:05:01,785 views 2888 14064 Registration error: 'EncryptionService' object has no attribute 'check_duplicate_ssn'
ERROR 2025-10-26 13:05:01,786 log 2888 14064 Internal Server Error: /api/auth/register/
INFO 2025-10-26 13:06:02,394 autoreload 7636 21516 C:\Users\Sakshi kumari\Documents\hclhackathon2025\smartbank\smartbank\settings.py changed, reloading.
INFO 2025-10-26 13:06:02,468 autoreload 2888 14424 C:\Users\Sakshi kumari\Documents\hclhackathon2025\smartbank\smartbank\settings.py changed, reloading.
INFO 2025-10-26 13:06:05,270 autoreload 19944 21556 Watching for file changes with StatReloader
INFO 2025-10-26 13:06:10,638 autoreload 16924 13856 C:\Users\Sakshi kumari\Documents\hclhackathon2025\smartbank\smartbank\celery.py changed, reloading.
INFO 2025-10-26 13:06:10,797 autoreload 19944 21556 C:\Users\Sakshi kumari\Documents\hclhackathon2025\smartbank\smartbank\celery.py changed, reloading.
INFO 2025-10-26 13:06:12,804 autoreload 9156 8264 Watching for file changes with StatReloader
INFO 2025-10-26 13:06:12,891 autoreload 22796 20764 Watching for file changes with StatReloader
INFO 2025-10-26 13:06:16,854 autoreload 9156 8264 C:\Users\Sakshi kumari\Documents\hclhackathon2025\smartbank\registration\tasks.py changed, reloading.
INFO 2025-10-26 13:06:16,857 autoreload 22796 20764 C:\Users\Sakshi kumari\Documents\hclhackathon2025\smartbank\registration\tasks.py changed, reloading.
INFO 2025-10-26 13:06:19,130 autoreload 9700 16876 Watching for file changes with StatReloader
INFO 2025-10-26 13:06:19,157 autoreload 1984 19740 Watching for file changes with StatReloader
INFO 2025-10-26 13:06:26,811 autoreload 1984 19740 C:\Users\Sakshi kumari\Documents\hclhackathon2025\smartbank\registration\tasks.py changed, reloading.
INFO 2025-10-26 13:06:26,910 autoreload 9700 16876 C:\Users\Sakshi kumari\Documents\hclhackathon2025\smartbank\registration\tasks.py changed, reloading.
INFO 2025-10-26 13:06:29,578 autoreload 308 18852 Watching for file changes with StatReloader
INFO 2025-10-26 13:06:29,726 autoreload 20168 22764 Watching for file changes with StatReloader
INFO 2025-10-26 13:07:13,111 autoreload 308 18852 C:\Users\Sakshi kumari\Documents\hclhackathon2025\smartbank\smartbank\settings.py changed, reloading.
INFO 2025-10-26 13:07:13,131 autoreload 20168 22764 C:\Users\Sakshi kumari\Documents\hclhackathon2025\smartbank\smartbank\settings.py changed, reloading.
INFO 2025-10-26 13:07:15,422 autoreload 22960 15696 Watching for file changes with StatReloader
INFO 2025-10-26 13:07:15,425 autoreload 23540 21564 Watching for file changes with StatReloader
INFO 2025-10-26 13:07:59,531 autoreload 22972 23416 Watching for file changes with StatReloader
WARNING 2025-10-26 13:08:00,827 utils 23540 8648 Security event logged: RATE_LIMIT_EXCEEDED - Rate limit exceeded for /api/auth/register/
WARNING 2025-10-26 13:08:00,827 log 23540 8648 Too Many Requests: /api/auth/register/
WARNING 2025-10-26 13:08:13,015 utils 23540 8648 Security event logged: RATE_LIMIT_EXCEEDED - Rate limit exceeded for /api/auth/register/
WARNING 2025-10-26 13:08:13,018 log 23540 8648 Too Many Requests: /api/auth/register/
WARNING 2025-10-26 13:09:20,116 utils 23540 8648 Security event logged: RATE_LIMIT_EXCEEDED - Rate limit exceeded for /api/auth/register/
WARNING 2025-10-26 13:09:20,119 log 23540 8648 Too Many Requests: /api/auth/register/
WARNING 2025-10-26 13:09:57,157 utils 23540 8648 Security event logged: RATE_LIMIT_EXCEEDED - Rate limit exceeded for /api/auth/register/
WARNING 2025-10-26 13:09:57,158 log 23540 8648 Too Many Requests: /api/auth/register/
INFO 2025-10-26 13:11:05,014 autoreload 23540 21564 C:\Users\Sakshi kumari\Documents\hclhackathon2025\smartbank\smartbank\settings.py changed, reloading.
INFO 2025-10-26 13:11:05,148 autoreload 22972 23416 C:\Users\Sakshi kumari\Documents\hclhackathon2025\smartbank\smartbank\settings.py changed, reloading.
INFO 2025-10-26 13:11:08,341 autoreload 20944 24120 Watching for file changes with StatReloader
INFO 2025-10-26 13:11:08,354 autoreload 13848 2104 Watching for file changes with StatReloader
INFO 2025-10-26 13:11:13,478 autoreload 20944 24120 C:\Users\Sakshi kumari\Documents\hclhackathon2025\smartbank\registration\middleware.py changed, reloading.
INFO 2025-10-26 13:11:13,615 autoreload 13848 2104 C:\Users\Sakshi kumari\Documents\hclhackathon2025\smartbank\registration\middleware.py changed, reloading.
INFO 2025-10-26 13:11:16,410 autoreload 23856 22852 Watching for file changes with StatReloader
INFO 2025-10-26 13:11:16,415 autoreload 21644 9832 Watching for file changes with StatReloader
INFO 2025-10-26 13:11:19,633 autoreload 21644 9832 C:\Users\Sakshi kumari\Documents\hclhackathon2025\smartbank\smartbank\settings.py changed, reloading.
INFO 2025-10-26 13:11:19,683 autoreload 23856 22852 C:\Users\Sakshi kumari\Documents\hclhackathon2025\smartbank\smartbank\settings.py changed, reloading.
INFO 2025-10-26 13:11:22,349 autoreload 24204 24164 Watching for file changes with StatReloader
INFO 2025-10-26 13:11:22,372 autoreload 23992 14064 Watching for file changes with StatReloader
INFO 2025-10-26 13:11:49,466 autoreload 23992 14064 C:\Users\Sakshi kumari\Documents\hclhackathon2025\smartbank\smartbank\settings.py changed, reloading.
INFO 2025-10-26 13:11:49,687 autoreload 24204 24164 C:\Users\Sakshi kumari\Documents\hclhackathon2025\smartbank\smartbank\settings.py changed, reloading.
INFO 2025-10-26 13:11:52,869 autoreload 23592 23648 Watching for file changes with StatReloader
INFO 2025-10-26 13:11:52,923 autoreload 12112 21640 Watching for file changes with StatReloader
INFO 2025-10-26 13:12:02,264 autoreload 12112 21640 C:\Users\Sakshi kumari\Documents\hclhackathon2025\smartbank\smartbank\settings.py changed, reloading.
INFO 2025-10-26 13:12:02,294 autoreload 23592 23648 C:\Users\Sakshi kumari\Documents\hclhackathon2025\smartbank\smartbank\settings.py changed, reloading.
INFO 2025-10-26 13:12:05,794 autoreload 24096 22864 Watching for file changes with StatReloader
INFO 2025-10-26 13:12:05,799 autoreload 24080 23336 Watching for file changes with StatReloader
ERROR 2025-10-26 13:12:45,948 views 24080 24212 Registration error: 'EncryptionService' object has no attribute 'check_duplicate_ssn'
ERROR 2025-10-26 13:12:45,951 log 24080 24212 Internal Server Error: /api/auth/register/
ERROR 2025-10-26 13:13:02,380 views 24080 24212 Registration error: 'EncryptionService' object has no attribute 'check_duplicate_ssn'
ERROR 2025-10-26 13:13:02,381 log 24080 24212 Internal Server Error: /api/auth/register/
INFO 2025-10-26 13:14:17,964 autoreload 24096 22864 C:\Users\Sakshi kumari\Documents\hclhackathon2025\smartbank\smartbank\celery.py changed, reloading.
INFO 2025-10-26 13:14:17,970 autoreload 24080 23336 C:\Users\Sakshi kumari\Documents\hclhackathon2025\smartbank\smartbank\celery.py changed, reloading.
INFO 2025-10-26 13:14:20,104 autoreload 23640 22336 Watching for file changes with StatReloader
INFO 2025-10-26 13:14:20,180 autoreload 16876 22656 Watching for file changes with StatReloader
INFO 2025-10-26 13:14:30,452 autoreload 23640 22336 C:\Users\Sakshi kumari\Documents\hclhackathon2025\smartbank\smartbank\settings.py changed, reloading.
INFO 2025-10-26 13:14:30,552 autoreload 16876 22656 C:\Users\Sakshi kumari\Documents\hclhackathon2025\smartbank\smartbank\settings.py changed, reloading.
INFO 2025-10-26 13:14:32,998 autoreload 22992 23464 Watching for file changes with StatReloader
INFO 2025-10-26 13:14:33,465 autoreload 23820 8736 Watching for file changes with StatReloader
INFO 2025-10-26 13:15:13,576 autoreload 23820 8736 C:\Users\Sakshi kumari\Documents\hclhackathon2025\smartbank\smartbank\celery.py changed, reloading.
INFO 2025-10-26 13:15:13,683 autoreload 22992 23464 C:\Users\Sakshi kumari\Documents\hclhackathon2025\smartbank\smartbank\settings.py changed, reloading.
INFO 2025-10-26 13:15:16,431 autoreload 23836 24160 Watching for file changes with StatReloader
INFO 2025-10-26 13:15:16,633 autoreload 8008 23416 Watching for file changes with StatReloader
ERROR 2025-10-26 13:15:25,688 views 23836 23396 Registration error: 'EncryptionService' object has no attribute 'check_duplicate_ssn'
ERROR 2025-10-26 13:15:25,689 log 23836 23396 Internal Server Error: /api/auth/register/
WARNING 2025-10-26 13:15:38,431 warnings 18716 24548 C:\Users\Sakshi kumari\AppData\Local\Programs\Python\Python310\lib\site-packages\billiard\pool.py:1022: UserWarning: Soft timeouts are not supported: on this platform: It does not have the SIGUSR1 signal.
  warnings.warn(UserWarning(

WARNING 2025-10-26 13:15:38,510 warnings 18716 24548 C:\Users\Sakshi kumari\AppData\Local\Programs\Python\Python310\lib\site-packages\celery\worker\consumer\consumer.py:507: CPendingDeprecationWarning: The broker_connection_retry configuration setting will no longer determine
whether broker connection retries are made during startup in Celery 6.0 and above.
If you wish to retain the existing behavior for retrying connections on startup,
you should set broker_connection_retry_on_startup to True.
  warnings.warn(

INFO 2025-10-26 13:15:38,523 connection 18716 24548 Connected to redis://localhost:6379/0
WARNING 2025-10-26 13:15:38,524 warnings 18716 24548 C:\Users\Sakshi kumari\AppData\Local\Programs\Python\Python310\lib\site-packages\celery\worker\consumer\consumer.py:507: CPendingDeprecationWarning: The broker_connection_retry configuration setting will no longer determine
whether broker connection retries are made during startup in Celery 6.0 and above.
If you wish to retain the existing behavior for retrying connections on startup,
you should set broker_connection_retry_on_startup to True.
  warnings.warn(

INFO 2025-10-26 13:15:38,534 mingle 18716 24548 mingle: searching for neighbors
INFO 2025-10-26 13:15:39,556 mingle 18716 24548 mingle: all alone
WARNING 2025-10-26 13:15:39,576 log 18716 24548 Celery worker is ready!
INFO 2025-10-26 13:15:39,577 worker 18716 24548 celery@LAPTOP-I39VB494 ready.
INFO 2025-10-26 13:15:48,302 autoreload 24068 16080 Watching for file changes with StatReloader
ERROR 2025-10-26 13:15:50,974 views 8008 22984 Registration error: 'EncryptionService' object has no attribute 'check_duplicate_ssn'
ERROR 2025-10-26 13:15:50,975 log 8008 22984 Internal Server Error: /api/auth/register/
WARNING 2025-10-26 13:15:59,392 log 8008 12568 Not Found: /favicon.ico
ERROR 2025-10-26 13:17:09,276 views 8008 22984 Registration error: 'EncryptionService' object has no attribute 'check_duplicate_ssn'
ERROR 2025-10-26 13:17:09,277 log 8008 22984 Internal Server Error: /api/auth/register/
ERROR 2025-10-26 13:17:28,153 utils 8008 22984 API Exception: Method "GET" not allowed. - {'view': <registration.views.UserRegistrationView object at 0x000001E1358476D0>, 'args': (), 'kwargs': {}, 'request': <rest_framework.request.Request: GET '/api/auth/register/'>}
WARNING 2025-10-26 13:17:28,155 log 8008 22984 Method Not Allowed: /api/auth/register/
ERROR 2025-10-26 13:17:40,893 utils 24068 9832 API Exception: Method "GET" not allowed. - {'view': <registration.views.UserRegistrationView object at 0x000001044F615F90>, 'args': (), 'kwargs': {}, 'request': <rest_framework.request.Request: GET '/api/auth/register/'>}
WARNING 2025-10-26 13:17:40,893 log 24068 9832 Method Not Allowed: /api/auth/register/
WARNING 2025-10-26 13:17:46,002 utils 24068 9832 Security event logged: RATE_LIMIT_EXCEEDED - Rate limit exceeded for /api/auth/register/
WARNING 2025-10-26 13:17:46,003 log 24068 9832 Too Many Requests: /api/auth/register/
INFO 2025-10-26 13:18:09,316 strategy 18716 24548 Task registration.tasks.monitor_system_health[6ba41c64-419a-4fc4-81cf-f1a4c4e7033e] received
WARNING 2025-10-26 13:18:09,319 warnings 18716 24548 C:\Users\Sakshi kumari\AppData\Local\Programs\Python\Python310\lib\site-packages\billiard\pool.py:1503: UserWarning: Soft timeouts are not supported: on this platform: It does not have the SIGUSR1 signal.
  warnings.warn(UserWarning(

ERROR 2025-10-26 13:18:09,354 request 18716 24524 Task handler raised error: ValueError('not enough values to unpack (expected 3, got 0)')
billiard.einfo.RemoteTraceback: 
"""
Traceback (most recent call last):
  File "C:\Users\Sakshi kumari\AppData\Local\Programs\Python\Python310\lib\site-packages\billiard\pool.py", line 362, in workloop
    result = (True, prepare_result(fun(*args, **kwargs)))
  File "C:\Users\Sakshi kumari\AppData\Local\Programs\Python\Python310\lib\site-packages\celery\app\trace.py", line 664, in fast_trace_task
    tasks, accept, hostname = _loc
ValueError: not enough values to unpack (expected 3, got 0)
"""

The above exception was the direct cause of the following exception:

Traceback (most recent call last):
  File "C:\Users\Sakshi kumari\AppData\Local\Programs\Python\Python310\lib\site-packages\billiard\pool.py", line 362, in workloop
    result = (True, prepare_result(fun(*args, **kwargs)))
  File "C:\Users\Sakshi kumari\AppData\Local\Programs\Python\Python310\lib\site-packages\celery\app\trace.py", line 664, in fast_trace_task
    tasks, accept, hostname = _loc
ValueError: not enough values to unpack (expected 3, got 0)
INFO 2025-10-26 13:18:14,053 autoreload 24068 16080 C:\Users\Sakshi kumari\Documents\hclhackathon2025\smartbank\smartbank\settings.py changed, reloading.
INFO 2025-10-26 13:18:15,666 autoreload 15264 22844 Watching for file changes with StatReloader
ERROR 2025-10-26 13:18:24,328 views 15264 9884 Registration error: 'EncryptionService' object has no attribute 'check_duplicate_ssn'
ERROR 2025-10-26 13:18:24,329 log 15264 9884 Internal Server Error: /api/auth/register/
INFO 2025-10-26 13:19:14,191 autoreload 15264 22844 C:\Users\Sakshi kumari\Documents\hclhackathon2025\smartbank\registration\utils.py changed, reloading.
INFO 2025-10-26 13:19:18,919 autoreload 10028 16600 Watching for file changes with StatReloader
ERROR 2025-10-26 13:21:04,704 utils 24268 23076 SSN encryption failed: ['Invalid SSN number']
ERROR 2025-10-26 13:21:35,376 utils 10316 22752 SSN encryption failed: Fernet key must be 32 url-safe base64-encoded bytes.
ERROR 2025-10-26 13:21:35,485 utils 10316 22752 SSN encryption failed: Fernet key must be 32 url-safe base64-encoded bytes.
ERROR 2025-10-26 13:21:35,485 utils 10316 22752 SSN duplicate check failed: ['Failed to encrypt SSN']
INFO 2025-10-26 13:21:52,562 autoreload 10028 16600 C:\Users\Sakshi kumari\Documents\hclhackathon2025\smartbank\smartbank\settings.py changed, reloading.
INFO 2025-10-26 13:21:54,793 autoreload 24488 21720 Watching for file changes with StatReloader
INFO 2025-10-26 13:22:19,882 autoreload 24488 21720 C:\Users\Sakshi kumari\Documents\hclhackathon2025\smartbank\registration\utils.py changed, reloading.
INFO 2025-10-26 13:22:21,777 autoreload 23132 23784 Watching for file changes with StatReloader
INFO 2025-10-26 13:22:31,165 autoreload 23132 23784 C:\Users\Sakshi kumari\Documents\hclhackathon2025\smartbank\smartbank\settings.py changed, reloading.
INFO 2025-10-26 13:22:33,483 autoreload 22476 22124 Watching for file changes with StatReloader
INFO 2025-10-26 13:22:49,892 utils 22476 18952 Assigned CUSTOMER role to user test_user
INFO 2025-10-26 13:22:49,909 utils 22476 18952 Audit log created: CREATE - User registered: test_user
INFO 2025-10-26 13:22:50,043 strategy 18716 24548 Task registration.tasks.notify_admin_new_registration[13018aa9-3f66-4252-9f1a-8ebba2f5e6be] received
ERROR 2025-10-26 13:22:50,108 request 18716 24524 Task handler raised error: ValueError('not enough values to unpack (expected 3, got 0)')
billiard.einfo.RemoteTraceback: 
"""
Traceback (most recent call last):
  File "C:\Users\Sakshi kumari\AppData\Local\Programs\Python\Python310\lib\site-packages\billiard\pool.py", line 362, in workloop
    result = (True, prepare_result(fun(*args, **kwargs)))
  File "C:\Users\Sakshi kumari\AppData\Local\Programs\Python\Python310\lib\site-packages\celery\app\trace.py", line 664, in fast_trace_task
    tasks, accept, hostname = _loc
ValueError: not enough values to unpack (expected 3, got 0)
"""

The above exception was the direct cause of the following exception:

Traceback (most recent call last):
  File "C:\Users\Sakshi kumari\AppData\Local\Programs\Python\Python310\lib\site-packages\billiard\pool.py", line 362, in workloop
    result = (True, prepare_result(fun(*args, **kwargs)))
  File "C:\Users\Sakshi kumari\AppData\Local\Programs\Python\Python310\lib\site-packages\celery\app\trace.py", line 664, in fast_trace_task
    tasks, accept, hostname = _loc
ValueError: not enough values to unpack (expected 3, got 0)
INFO 2025-10-26 13:23:09,374 strategy 18716 24548 Task registration.tasks.monitor_system_health[34598d6e-8bce-4af4-bff7-acf50ad04619] received
ERROR 2025-10-26 13:23:09,420 request 18716 24524 Task handler raised error: ValueError('not enough values to unpack (expected 3, got 0)')
billiard.einfo.RemoteTraceback: 
"""
Traceback (most recent call last):
  File "C:\Users\Sakshi kumari\AppData\Local\Programs\Python\Python310\lib\site-packages\billiard\pool.py", line 362, in workloop
    result = (True, prepare_result(fun(*args, **kwargs)))
  File "C:\Users\Sakshi kumari\AppData\Local\Programs\Python\Python310\lib\site-packages\celery\app\trace.py", line 664, in fast_trace_task
    tasks, accept, hostname = _loc
ValueError: not enough values to unpack (expected 3, got 0)
"""

The above exception was the direct cause of the following exception:

Traceback (most recent call last):
  File "C:\Users\Sakshi kumari\AppData\Local\Programs\Python\Python310\lib\site-packages\billiard\pool.py", line 362, in workloop
    result = (True, prepare_result(fun(*args, **kwargs)))
  File "C:\Users\Sakshi kumari\AppData\Local\Programs\Python\Python310\lib\site-packages\celery\app\trace.py", line 664, in fast_trace_task
    tasks, accept, hostname = _loc
ValueError: not enough values to unpack (expected 3, got 0)
ERROR 2025-10-26 13:26:04,908 log 22476 18952 Internal Server Error: /api/auth/login
Traceback (most recent call last):
  File "C:\Users\Sakshi kumari\AppData\Local\Programs\Python\Python310\lib\site-packages\django\core\handlers\exception.py", line 55, in inner
    response = get_response(request)
  File "C:\Users\Sakshi kumari\AppData\Local\Programs\Python\Python310\lib\site-packages\django\utils\deprecation.py", line 136, in __call__
    response = self.process_response(request, response)
  File "C:\Users\Sakshi kumari\AppData\Local\Programs\Python\Python310\lib\site-packages\django\middleware\common.py", line 108, in process_response
    return self.response_redirect_class(self.get_full_path_with_slash(request))
  File "C:\Users\Sakshi kumari\AppData\Local\Programs\Python\Python310\lib\site-packages\django\middleware\common.py", line 87, in get_full_path_with_slash
    raise RuntimeError(
RuntimeError: You called this URL via POST, but the URL doesn't end in a slash and you have APPEND_SLASH set. Django can't redirect to the slash URL while maintaining POST data. Change your form to point to localhost:8000/api/auth/login/ (note the trailing slash), or set APPEND_SLASH=False in your Django settings.
INFO 2025-10-26 13:26:21,311 utils 22476 23376 Audit log created: LOGIN - User logged in: test_user
INFO 2025-10-26 13:28:09,431 strategy 18716 24548 Task registration.tasks.monitor_system_health[6549ae26-d985-40e1-b653-7fe9e5cb62b0] received
ERROR 2025-10-26 13:28:09,624 request 18716 24524 Task handler raised error: ValueError('not enough values to unpack (expected 3, got 0)')
billiard.einfo.RemoteTraceback: 
"""
Traceback (most recent call last):
  File "C:\Users\Sakshi kumari\AppData\Local\Programs\Python\Python310\lib\site-packages\billiard\pool.py", line 362, in workloop
    result = (True, prepare_result(fun(*args, **kwargs)))
  File "C:\Users\Sakshi kumari\AppData\Local\Programs\Python\Python310\lib\site-packages\celery\app\trace.py", line 664, in fast_trace_task
    tasks, accept, hostname = _loc
ValueError: not enough values to unpack (expected 3, got 0)
"""

The above exception was the direct cause of the following exception:

Traceback (most recent call last):
  File "C:\Users\Sakshi kumari\AppData\Local\Programs\Python\Python310\lib\site-packages\billiard\pool.py", line 362, in workloop
    result = (True, prepare_result(fun(*args, **kwargs)))
  File "C:\Users\Sakshi kumari\AppData\Local\Programs\Python\Python310\lib\site-packages\celery\app\trace.py", line 664, in fast_trace_task
    tasks, accept, hostname = _loc
ValueError: not enough values to unpack (expected 3, got 0)
CRITICAL 2025-10-26 13:28:10,493 worker 18716 24548 Unrecoverable error: ResponseError("MISCONF Redis is configured to save RDB snapshots, but it's currently unable to persist to disk. Commands that may modify the data set are disabled, because this instance is configured to report errors during writes if RDB snapshotting fails (stop-writes-on-bgsave-error option). Please check the Redis logs for details about the RDB error.")
Traceback (most recent call last):
  File "C:\Users\Sakshi kumari\AppData\Local\Programs\Python\Python310\lib\site-packages\celery\worker\worker.py", line 202, in start
    self.blueprint.start(self)
  File "C:\Users\Sakshi kumari\AppData\Local\Programs\Python\Python310\lib\site-packages\celery\bootsteps.py", line 116, in start
    step.start(parent)
  File "C:\Users\Sakshi kumari\AppData\Local\Programs\Python\Python310\lib\site-packages\celery\bootsteps.py", line 365, in start
    return self.obj.start()
  File "C:\Users\Sakshi kumari\AppData\Local\Programs\Python\Python310\lib\site-packages\celery\worker\consumer\consumer.py", line 340, in start
    blueprint.start(self)
  File "C:\Users\Sakshi kumari\AppData\Local\Programs\Python\Python310\lib\site-packages\celery\bootsteps.py", line 116, in start
    step.start(parent)
  File "C:\Users\Sakshi kumari\AppData\Local\Programs\Python\Python310\lib\site-packages\celery\worker\consumer\consumer.py", line 742, in start
    c.loop(*c.loop_args())
  File "C:\Users\Sakshi kumari\AppData\Local\Programs\Python\Python310\lib\site-packages\celery\worker\loops.py", line 130, in synloop
    connection.drain_events(timeout=2.0)
  File "C:\Users\Sakshi kumari\AppData\Local\Programs\Python\Python310\lib\site-packages\kombu\connection.py", line 341, in drain_events
    return self.transport.drain_events(self.connection, **kwargs)
  File "C:\Users\Sakshi kumari\AppData\Local\Programs\Python\Python310\lib\site-packages\kombu\transport\virtual\base.py", line 997, in drain_events
    get(self._deliver, timeout=timeout)
  File "C:\Users\Sakshi kumari\AppData\Local\Programs\Python\Python310\lib\site-packages\kombu\transport\redis.py", line 591, in get
    ret = self.handle_event(fileno, event)
  File "C:\Users\Sakshi kumari\AppData\Local\Programs\Python\Python310\lib\site-packages\kombu\transport\redis.py", line 573, in handle_event
    return self.on_readable(fileno), self
  File "C:\Users\Sakshi kumari\AppData\Local\Programs\Python\Python310\lib\site-packages\kombu\transport\redis.py", line 569, in on_readable
    chan.handlers[type]()
  File "C:\Users\Sakshi kumari\AppData\Local\Programs\Python\Python310\lib\site-packages\kombu\transport\redis.py", line 967, in _brpop_read
    dest__item = self.client.parse_response(self.client.connection,
  File "C:\Users\Sakshi kumari\AppData\Local\Programs\Python\Python310\lib\site-packages\redis\client.py", line 553, in parse_response
    response = connection.read_response()
  File "C:\Users\Sakshi kumari\AppData\Local\Programs\Python\Python310\lib\site-packages\redis\connection.py", line 524, in read_response
    raise response
redis.exceptions.ResponseError: MISCONF Redis is configured to save RDB snapshots, but it's currently unable to persist to disk. Commands that may modify the data set are disabled, because this instance is configured to report errors during writes if RDB snapshotting fails (stop-writes-on-bgsave-error option). Please check the Redis logs for details about the RDB error.
WARNING 2025-10-26 13:28:11,621 log 18716 24548 Celery worker is shutting down!
ERROR 2025-10-26 13:31:52,300 utils 22476 23376 Rate limit check failed: MISCONF Redis is configured to save RDB snapshots, but it's currently unable to persist to disk. Commands that may modify the data set are disabled, because this instance is configured to report errors during writes if RDB snapshotting fails (stop-writes-on-bgsave-error option). Please check the Redis logs for details about the RDB error.
ERROR 2025-10-26 13:31:52,375 utils 22476 23376 API Exception: Method "GET" not allowed. - {'view': <registration.views.KYCDocumentUploadView object at 0x00000220C4026890>, 'args': (), 'kwargs': {}, 'request': <rest_framework.request.Request: GET '/api/kyc/upload/'>}
WARNING 2025-10-26 13:31:52,376 log 22476 23376 Method Not Allowed: /api/kyc/upload/
ERROR 2025-10-26 13:31:56,342 utils 22476 23376 Rate limit check failed: MISCONF Redis is configured to save RDB snapshots, but it's currently unable to persist to disk. Commands that may modify the data set are disabled, because this instance is configured to report errors during writes if RDB snapshotting fails (stop-writes-on-bgsave-error option). Please check the Redis logs for details about the RDB error.
WARNING 2025-10-26 13:31:56,417 log 22476 23376 Bad Request: /api/kyc/upload/
ERROR 2025-10-26 13:32:10,249 utils 22476 23376 Rate limit check failed: MISCONF Redis is configured to save RDB snapshots, but it's currently unable to persist to disk. Commands that may modify the data set are disabled, because this instance is configured to report errors during writes if RDB snapshotting fails (stop-writes-on-bgsave-error option). Please check the Redis logs for details about the RDB error.
WARNING 2025-10-26 13:32:10,322 log 22476 23376 Bad Request: /api/kyc/upload/
ERROR 2025-10-26 13:32:28,593 utils 22476 23376 Rate limit check failed: MISCONF Redis is configured to save RDB snapshots, but it's currently unable to persist to disk. Commands that may modify the data set are disabled, because this instance is configured to report errors during writes if RDB snapshotting fails (stop-writes-on-bgsave-error option). Please check the Redis logs for details about the RDB error.
WARNING 2025-10-26 13:32:28,667 log 22476 23376 Bad Request: /api/kyc/upload/
ERROR 2025-10-26 13:32:55,805 utils 22476 23376 Rate limit check failed: MISCONF Redis is configured to save RDB snapshots, but it's currently unable to persist to disk. Commands that may modify the data set are disabled, because this instance is configured to report errors during writes if RDB snapshotting fails (stop-writes-on-bgsave-error option). Please check the Redis logs for details about the RDB error.
ERROR 2025-10-26 13:32:55,901 views 22476 23376 KYC upload error: 'bytes' object has no attribute 'read'
ERROR 2025-10-26 13:32:55,901 log 22476 23376 Internal Server Error: /api/kyc/upload/
INFO 2025-10-26 13:35:47,143 autoreload 22476 22124 C:\Users\Sakshi kumari\Documents\hclhackathon2025\smartbank\smartbank\settings.py changed, reloading.
INFO 2025-10-26 13:35:50,044 autoreload 24148 22808 Watching for file changes with StatReloader
INFO 2025-10-26 13:36:07,474 autoreload 24148 22808 C:\Users\Sakshi kumari\Documents\hclhackathon2025\smartbank\registration\serializers.py changed, reloading.
INFO 2025-10-26 13:36:09,577 autoreload 20176 22532 Watching for file changes with StatReloader
INFO 2025-10-26 13:36:18,975 autoreload 20176 22532 C:\Users\Sakshi kumari\Documents\hclhackathon2025\smartbank\registration\serializers.py changed, reloading.
INFO 2025-10-26 13:36:24,149 autoreload 24200 23008 Watching for file changes with StatReloader
INFO 2025-10-26 13:36:32,994 autoreload 24200 23008 C:\Users\Sakshi kumari\Documents\hclhackathon2025\smartbank\registration\middleware.py changed, reloading.
INFO 2025-10-26 13:36:37,585 autoreload 23748 24688 Watching for file changes with StatReloader
INFO 2025-10-26 13:38:24,596 autoreload 23748 24688 C:\Users\Sakshi kumari\Documents\hclhackathon2025\smartbank\registration\middleware.py changed, reloading.
INFO 2025-10-26 13:38:26,876 autoreload 24032 24724 Watching for file changes with StatReloader
INFO 2025-10-26 13:38:34,912 autoreload 24032 24724 C:\Users\Sakshi kumari\Documents\hclhackathon2025\smartbank\smartbank\settings.py changed, reloading.
INFO 2025-10-26 13:38:37,346 autoreload 25520 25296 Watching for file changes with StatReloader
WARNING 2025-10-26 13:38:53,741 warnings 6564 23900 C:\Users\Sakshi kumari\AppData\Local\Programs\Python\Python310\lib\site-packages\billiard\pool.py:1022: UserWarning: Soft timeouts are not supported: on this platform: It does not have the SIGUSR1 signal.
  warnings.warn(UserWarning(

WARNING 2025-10-26 13:38:53,801 warnings 6564 23900 C:\Users\Sakshi kumari\AppData\Local\Programs\Python\Python310\lib\site-packages\celery\worker\consumer\consumer.py:507: CPendingDeprecationWarning: The broker_connection_retry configuration setting will no longer determine
whether broker connection retries are made during startup in Celery 6.0 and above.
If you wish to retain the existing behavior for retrying connections on startup,
you should set broker_connection_retry_on_startup to True.
  warnings.warn(

INFO 2025-10-26 13:38:53,808 connection 6564 23900 Connected to redis://localhost:6379/0
WARNING 2025-10-26 13:38:53,809 warnings 6564 23900 C:\Users\Sakshi kumari\AppData\Local\Programs\Python\Python310\lib\site-packages\celery\worker\consumer\consumer.py:507: CPendingDeprecationWarning: The broker_connection_retry configuration setting will no longer determine
whether broker connection retries are made during startup in Celery 6.0 and above.
If you wish to retain the existing behavior for retrying connections on startup,
you should set broker_connection_retry_on_startup to True.
  warnings.warn(

INFO 2025-10-26 13:38:53,817 mingle 6564 23900 mingle: searching for neighbors
INFO 2025-10-26 13:38:54,853 mingle 6564 23900 mingle: all alone
WARNING 2025-10-26 13:38:54,873 log 6564 23900 Celery worker is ready!
INFO 2025-10-26 13:38:54,873 worker 6564 23900 celery@LAPTOP-I39VB494 ready.
INFO 2025-10-26 13:38:54,876 strategy 6564 23900 Task registration.tasks.monitor_system_health[140c68db-7891-4818-9704-e42c34898798] received
WARNING 2025-10-26 13:38:54,881 warnings 6564 23900 C:\Users\Sakshi kumari\AppData\Local\Programs\Python\Python310\lib\site-packages\billiard\pool.py:1503: UserWarning: Soft timeouts are not supported: on this platform: It does not have the SIGUSR1 signal.
  warnings.warn(UserWarning(

ERROR 2025-10-26 13:38:56,815 request 6564 25380 Task handler raised error: ValueError('not enough values to unpack (expected 3, got 0)')
billiard.einfo.RemoteTraceback: 
"""
Traceback (most recent call last):
  File "C:\Users\Sakshi kumari\AppData\Local\Programs\Python\Python310\lib\site-packages\billiard\pool.py", line 362, in workloop
    result = (True, prepare_result(fun(*args, **kwargs)))
  File "C:\Users\Sakshi kumari\AppData\Local\Programs\Python\Python310\lib\site-packages\celery\app\trace.py", line 664, in fast_trace_task
    tasks, accept, hostname = _loc
ValueError: not enough values to unpack (expected 3, got 0)
"""

The above exception was the direct cause of the following exception:

Traceback (most recent call last):
  File "C:\Users\Sakshi kumari\AppData\Local\Programs\Python\Python310\lib\site-packages\billiard\pool.py", line 362, in workloop
    result = (True, prepare_result(fun(*args, **kwargs)))
  File "C:\Users\Sakshi kumari\AppData\Local\Programs\Python\Python310\lib\site-packages\celery\app\trace.py", line 664, in fast_trace_task
    tasks, accept, hostname = _loc
ValueError: not enough values to unpack (expected 3, got 0)
ERROR 2025-10-26 13:39:11,424 serializers 25520 2560 KYC document processing error: 'bytes' object has no attribute 'read'
ERROR 2025-10-26 13:39:11,426 views 25520 2560 KYC upload error: [ErrorDetail(string="Failed to process document: 'bytes' object has no attribute 'read'", code='invalid')]
ERROR 2025-10-26 13:39:11,427 log 25520 2560 Internal Server Error: /api/kyc/upload/
WARNING 2025-10-26 13:39:21,448 log 25520 2560 Bad Request: /api/kyc/upload/
ERROR 2025-10-26 13:39:45,202 serializers 25520 2560 KYC document processing error: 'bytes' object has no attribute 'read'
ERROR 2025-10-26 13:39:45,203 views 25520 2560 KYC upload error: [ErrorDetail(string="Failed to process document: 'bytes' object has no attribute 'read'", code='invalid')]
ERROR 2025-10-26 13:39:45,203 log 25520 2560 Internal Server Error: /api/kyc/upload/
INFO 2025-10-26 13:43:09,609 strategy 6564 23900 Task registration.tasks.monitor_system_health[862bb070-a05b-4b75-842b-9e8313148e2c] received
ERROR 2025-10-26 13:43:09,615 request 6564 25380 Task handler raised error: ValueError('not enough values to unpack (expected 3, got 0)')
billiard.einfo.RemoteTraceback: 
"""
Traceback (most recent call last):
  File "C:\Users\Sakshi kumari\AppData\Local\Programs\Python\Python310\lib\site-packages\billiard\pool.py", line 362, in workloop
    result = (True, prepare_result(fun(*args, **kwargs)))
  File "C:\Users\Sakshi kumari\AppData\Local\Programs\Python\Python310\lib\site-packages\celery\app\trace.py", line 664, in fast_trace_task
    tasks, accept, hostname = _loc
ValueError: not enough values to unpack (expected 3, got 0)
"""

The above exception was the direct cause of the following exception:

Traceback (most recent call last):
  File "C:\Users\Sakshi kumari\AppData\Local\Programs\Python\Python310\lib\site-packages\billiard\pool.py", line 362, in workloop
    result = (True, prepare_result(fun(*args, **kwargs)))
  File "C:\Users\Sakshi kumari\AppData\Local\Programs\Python\Python310\lib\site-packages\celery\app\trace.py", line 664, in fast_trace_task
    tasks, accept, hostname = _loc
ValueError: not enough values to unpack (expected 3, got 0)
INFO 2025-10-26 13:48:09,667 strategy 6564 23900 Task registration.tasks.monitor_system_health[68a92ae3-5ff4-4d18-add7-02c716705942] received
ERROR 2025-10-26 13:48:09,684 request 6564 25380 Task handler raised error: ValueError('not enough values to unpack (expected 3, got 0)')
billiard.einfo.RemoteTraceback: 
"""
Traceback (most recent call last):
  File "C:\Users\Sakshi kumari\AppData\Local\Programs\Python\Python310\lib\site-packages\billiard\pool.py", line 362, in workloop
    result = (True, prepare_result(fun(*args, **kwargs)))
  File "C:\Users\Sakshi kumari\AppData\Local\Programs\Python\Python310\lib\site-packages\celery\app\trace.py", line 664, in fast_trace_task
    tasks, accept, hostname = _loc
ValueError: not enough values to unpack (expected 3, got 0)
"""

The above exception was the direct cause of the following exception:

Traceback (most recent call last):
  File "C:\Users\Sakshi kumari\AppData\Local\Programs\Python\Python310\lib\site-packages\billiard\pool.py", line 362, in workloop
    result = (True, prepare_result(fun(*args, **kwargs)))
  File "C:\Users\Sakshi kumari\AppData\Local\Programs\Python\Python310\lib\site-packages\celery\app\trace.py", line 664, in fast_trace_task
    tasks, accept, hostname = _loc
ValueError: not enough values to unpack (expected 3, got 0)
INFO 2025-10-26 13:53:09,755 strategy 6564 23900 Task registration.tasks.monitor_system_health[fab275c5-76c7-4d62-9137-9113a2420532] received
ERROR 2025-10-26 13:53:09,955 request 6564 25380 Task handler raised error: ValueError('not enough values to unpack (expected 3, got 0)')
billiard.einfo.RemoteTraceback: 
"""
Traceback (most recent call last):
  File "C:\Users\Sakshi kumari\AppData\Local\Programs\Python\Python310\lib\site-packages\billiard\pool.py", line 362, in workloop
    result = (True, prepare_result(fun(*args, **kwargs)))
  File "C:\Users\Sakshi kumari\AppData\Local\Programs\Python\Python310\lib\site-packages\celery\app\trace.py", line 664, in fast_trace_task
    tasks, accept, hostname = _loc
ValueError: not enough values to unpack (expected 3, got 0)
"""

The above exception was the direct cause of the following exception:

Traceback (most recent call last):
  File "C:\Users\Sakshi kumari\AppData\Local\Programs\Python\Python310\lib\site-packages\billiard\pool.py", line 362, in workloop
    result = (True, prepare_result(fun(*args, **kwargs)))
  File "C:\Users\Sakshi kumari\AppData\Local\Programs\Python\Python310\lib\site-packages\celery\app\trace.py", line 664, in fast_trace_task
    tasks, accept, hostname = _loc
ValueError: not enough values to unpack (expected 3, got 0)
INFO 2025-10-26 14:33:37,646 strategy 6564 23900 Task registration.tasks.monitor_system_health[4b334b45-3d70-4140-a829-faf9bfbaf345] received
ERROR 2025-10-26 14:33:38,173 request 6564 25380 Task handler raised error: ValueError('not enough values to unpack (expected 3, got 0)')
billiard.einfo.RemoteTraceback: 
"""
Traceback (most recent call last):
  File "C:\Users\Sakshi kumari\AppData\Local\Programs\Python\Python310\lib\site-packages\billiard\pool.py", line 362, in workloop
    result = (True, prepare_result(fun(*args, **kwargs)))
  File "C:\Users\Sakshi kumari\AppData\Local\Programs\Python\Python310\lib\site-packages\celery\app\trace.py", line 664, in fast_trace_task
    tasks, accept, hostname = _loc
ValueError: not enough values to unpack (expected 3, got 0)
"""

The above exception was the direct cause of the following exception:

Traceback (most recent call last):
  File "C:\Users\Sakshi kumari\AppData\Local\Programs\Python\Python310\lib\site-packages\billiard\pool.py", line 362, in workloop
    result = (True, prepare_result(fun(*args, **kwargs)))
  File "C:\Users\Sakshi kumari\AppData\Local\Programs\Python\Python310\lib\site-packages\celery\app\trace.py", line 664, in fast_trace_task
    tasks, accept, hostname = _loc
ValueError: not enough values to unpack (expected 3, got 0)
INFO 2025-10-26 14:33:38,668 strategy 6564 23900 Task registration.tasks.cleanup_expired_data[2cd667cf-5a0e-4450-ad69-acff46b6d079] received
ERROR 2025-10-26 14:33:38,747 request 6564 25380 Task handler raised error: ValueError('not enough values to unpack (expected 3, got 0)')
billiard.einfo.RemoteTraceback: 
"""
Traceback (most recent call last):
  File "C:\Users\Sakshi kumari\AppData\Local\Programs\Python\Python310\lib\site-packages\billiard\pool.py", line 362, in workloop
    result = (True, prepare_result(fun(*args, **kwargs)))
  File "C:\Users\Sakshi kumari\AppData\Local\Programs\Python\Python310\lib\site-packages\celery\app\trace.py", line 664, in fast_trace_task
    tasks, accept, hostname = _loc
ValueError: not enough values to unpack (expected 3, got 0)
"""

The above exception was the direct cause of the following exception:

Traceback (most recent call last):
  File "C:\Users\Sakshi kumari\AppData\Local\Programs\Python\Python310\lib\site-packages\billiard\pool.py", line 362, in workloop
    result = (True, prepare_result(fun(*args, **kwargs)))
  File "C:\Users\Sakshi kumari\AppData\Local\Programs\Python\Python310\lib\site-packages\celery\app\trace.py", line 664, in fast_trace_task
    tasks, accept, hostname = _loc
ValueError: not enough values to unpack (expected 3, got 0)
INFO 2025-10-26 14:35:16,352 autoreload 25520 25296 C:\Users\Sakshi kumari\Documents\hclhackathon2025\smartbank\registration\views.py changed, reloading.
INFO 2025-10-26 14:35:22,741 autoreload 28160 27964 Watching for file changes with StatReloader
INFO 2025-10-26 14:35:33,692 autoreload 28160 27964 C:\Users\Sakshi kumari\Documents\hclhackathon2025\smartbank\registration\views.py changed, reloading.
INFO 2025-10-26 14:35:36,400 autoreload 28244 23916 Watching for file changes with StatReloader
INFO 2025-10-26 14:35:42,031 autoreload 28244 23916 C:\Users\Sakshi kumari\Documents\hclhackathon2025\smartbank\registration\views.py changed, reloading.
INFO 2025-10-26 14:35:44,456 autoreload 27088 27908 Watching for file changes with StatReloader
ERROR 2025-10-26 14:36:53,046 serializers 2560 3024 KYC document processing error: 'bytes' object has no attribute 'read'
INFO 2025-10-26 14:37:04,680 autoreload 27088 27908 C:\Users\Sakshi kumari\Documents\hclhackathon2025\smartbank\registration\serializers.py changed, reloading.
INFO 2025-10-26 14:37:07,127 autoreload 17492 15904 Watching for file changes with StatReloader
ERROR 2025-10-26 14:37:11,078 utils 18448 25052 Failed to create audit log: 'MockRequest' object has no attribute 'META'
INFO 2025-10-26 14:37:29,432 utils 25784 25312 Audit log created: DOCUMENT_UPLOAD - Uploaded GOVERNMENT_ID document
INFO 2025-10-26 14:37:49,608 autoreload 17492 15904 C:\Users\Sakshi kumari\Documents\hclhackathon2025\smartbank\registration\serializers.py changed, reloading.
INFO 2025-10-26 14:37:52,192 autoreload 21532 28068 Watching for file changes with StatReloader
ERROR 2025-10-26 14:38:22,820 utils 21532 11632 API Exception: {'detail': ErrorDetail(string='Given token not valid for any token type', code='token_not_valid'), 'code': ErrorDetail(string='token_not_valid', code='token_not_valid'), 'messages': [{'token_class': ErrorDetail(string='AccessToken', code='token_not_valid'), 'token_type': ErrorDetail(string='access', code='token_not_valid'), 'message': ErrorDetail(string='Token is invalid or expired', code='token_not_valid')}]} - {'view': <registration.views.KYCDocumentUploadView object at 0x000001594B9D2F50>, 'args': (), 'kwargs': {}, 'request': <rest_framework.request.Request: POST '/api/kyc/upload/'>}
WARNING 2025-10-26 14:38:22,821 log 21532 11632 Unauthorized: /api/kyc/upload/
INFO 2025-10-26 14:38:36,877 utils 21532 11632 Audit log created: LOGIN - User logged in: test_user
INFO 2025-10-26 14:38:37,508 strategy 6564 23900 Task registration.tasks.monitor_system_health[6183f6c9-79a4-43cf-a996-8da6fba8a40a] received
ERROR 2025-10-26 14:38:37,526 request 6564 25380 Task handler raised error: ValueError('not enough values to unpack (expected 3, got 0)')
billiard.einfo.RemoteTraceback: 
"""
Traceback (most recent call last):
  File "C:\Users\Sakshi kumari\AppData\Local\Programs\Python\Python310\lib\site-packages\billiard\pool.py", line 362, in workloop
    result = (True, prepare_result(fun(*args, **kwargs)))
  File "C:\Users\Sakshi kumari\AppData\Local\Programs\Python\Python310\lib\site-packages\celery\app\trace.py", line 664, in fast_trace_task
    tasks, accept, hostname = _loc
ValueError: not enough values to unpack (expected 3, got 0)
"""

The above exception was the direct cause of the following exception:

Traceback (most recent call last):
  File "C:\Users\Sakshi kumari\AppData\Local\Programs\Python\Python310\lib\site-packages\billiard\pool.py", line 362, in workloop
    result = (True, prepare_result(fun(*args, **kwargs)))
  File "C:\Users\Sakshi kumari\AppData\Local\Programs\Python\Python310\lib\site-packages\celery\app\trace.py", line 664, in fast_trace_task
    tasks, accept, hostname = _loc
ValueError: not enough values to unpack (expected 3, got 0)
INFO 2025-10-26 14:38:53,983 utils 21532 11632 Audit log created: DOCUMENT_UPLOAD - Uploaded GOVERNMENT_ID document
INFO 2025-10-26 14:43:24,845 autoreload 21532 28068 C:\Users\Sakshi kumari\Documents\hclhackathon2025\smartbank\registration\utils.py changed, reloading.
INFO 2025-10-26 14:43:28,250 autoreload 25692 27476 Watching for file changes with StatReloader
INFO 2025-10-26 14:43:37,661 strategy 6564 23900 Task registration.tasks.monitor_system_health[f1c3a55b-27ac-49a9-ad2c-883d8f140438] received
ERROR 2025-10-26 14:43:37,701 request 6564 25380 Task handler raised error: ValueError('not enough values to unpack (expected 3, got 0)')
billiard.einfo.RemoteTraceback: 
"""
Traceback (most recent call last):
  File "C:\Users\Sakshi kumari\AppData\Local\Programs\Python\Python310\lib\site-packages\billiard\pool.py", line 362, in workloop
    result = (True, prepare_result(fun(*args, **kwargs)))
  File "C:\Users\Sakshi kumari\AppData\Local\Programs\Python\Python310\lib\site-packages\celery\app\trace.py", line 664, in fast_trace_task
    tasks, accept, hostname = _loc
ValueError: not enough values to unpack (expected 3, got 0)
"""

The above exception was the direct cause of the following exception:

Traceback (most recent call last):
  File "C:\Users\Sakshi kumari\AppData\Local\Programs\Python\Python310\lib\site-packages\billiard\pool.py", line 362, in workloop
    result = (True, prepare_result(fun(*args, **kwargs)))
  File "C:\Users\Sakshi kumari\AppData\Local\Programs\Python\Python310\lib\site-packages\celery\app\trace.py", line 664, in fast_trace_task
    tasks, accept, hostname = _loc
ValueError: not enough values to unpack (expected 3, got 0)
INFO 2025-10-26 14:44:05,036 autoreload 25692 27476 C:\Users\Sakshi kumari\Documents\hclhackathon2025\smartbank\registration\utils.py changed, reloading.
INFO 2025-10-26 14:44:07,700 autoreload 8952 13060 Watching for file changes with StatReloader
INFO 2025-10-26 14:46:00,172 utils 8952 22208 Audit log created: DOCUMENT_UPLOAD - Uploaded PASSPORT document
WARNING 2025-10-26 14:46:16,399 log 8952 22208 Bad Request: /api/kyc/upload/
ERROR 2025-10-26 14:48:12,411 utils 8952 22208 SSN encryption failed: ['Invalid SSN format']
ERROR 2025-10-26 14:48:12,411 utils 8952 22208 SSN duplicate check failed: ['Failed to encrypt SSN']
ERROR 2025-10-26 14:48:12,412 utils 8952 22208 SSN encryption failed: ['Invalid SSN format']
ERROR 2025-10-26 14:48:12,412 views 8952 22208 Registration error: ['Failed to encrypt SSN']
ERROR 2025-10-26 14:48:12,412 log 8952 22208 Internal Server Error: /api/auth/register/
INFO 2025-10-26 14:48:37,728 strategy 6564 23900 Task registration.tasks.monitor_system_health[19f65839-a626-498a-ad2b-182c790a2115] received
ERROR 2025-10-26 14:48:37,754 request 6564 25380 Task handler raised error: ValueError('not enough values to unpack (expected 3, got 0)')
billiard.einfo.RemoteTraceback: 
"""
Traceback (most recent call last):
  File "C:\Users\Sakshi kumari\AppData\Local\Programs\Python\Python310\lib\site-packages\billiard\pool.py", line 362, in workloop
    result = (True, prepare_result(fun(*args, **kwargs)))
  File "C:\Users\Sakshi kumari\AppData\Local\Programs\Python\Python310\lib\site-packages\celery\app\trace.py", line 664, in fast_trace_task
    tasks, accept, hostname = _loc
ValueError: not enough values to unpack (expected 3, got 0)
"""

The above exception was the direct cause of the following exception:

Traceback (most recent call last):
  File "C:\Users\Sakshi kumari\AppData\Local\Programs\Python\Python310\lib\site-packages\billiard\pool.py", line 362, in workloop
    result = (True, prepare_result(fun(*args, **kwargs)))
  File "C:\Users\Sakshi kumari\AppData\Local\Programs\Python\Python310\lib\site-packages\celery\app\trace.py", line 664, in fast_trace_task
    tasks, accept, hostname = _loc
ValueError: not enough values to unpack (expected 3, got 0)
INFO 2025-10-26 14:48:50,294 utils 8952 22208 Assigned CUSTOMER role to user sakshi
INFO 2025-10-26 14:48:50,298 utils 8952 22208 Audit log created: CREATE - User registered: sakshi
INFO 2025-10-26 14:49:32,551 utils 8952 22208 Audit log created: LOGIN - User logged in: sakshi
INFO 2025-10-26 14:50:01,804 utils 8952 22208 Audit log created: DOCUMENT_UPLOAD - Uploaded PASSPORT document
INFO 2025-10-26 14:53:37,970 strategy 6564 23900 Task registration.tasks.monitor_system_health[3dbc2389-aaa8-4eba-b1c4-47a1b6c32414] received
ERROR 2025-10-26 14:53:38,011 request 6564 25380 Task handler raised error: ValueError('not enough values to unpack (expected 3, got 0)')
billiard.einfo.RemoteTraceback: 
"""
Traceback (most recent call last):
  File "C:\Users\Sakshi kumari\AppData\Local\Programs\Python\Python310\lib\site-packages\billiard\pool.py", line 362, in workloop
    result = (True, prepare_result(fun(*args, **kwargs)))
  File "C:\Users\Sakshi kumari\AppData\Local\Programs\Python\Python310\lib\site-packages\celery\app\trace.py", line 664, in fast_trace_task
    tasks, accept, hostname = _loc
ValueError: not enough values to unpack (expected 3, got 0)
"""

The above exception was the direct cause of the following exception:

Traceback (most recent call last):
  File "C:\Users\Sakshi kumari\AppData\Local\Programs\Python\Python310\lib\site-packages\billiard\pool.py", line 362, in workloop
    result = (True, prepare_result(fun(*args, **kwargs)))
  File "C:\Users\Sakshi kumari\AppData\Local\Programs\Python\Python310\lib\site-packages\celery\app\trace.py", line 664, in fast_trace_task
    tasks, accept, hostname = _loc
ValueError: not enough values to unpack (expected 3, got 0)
INFO 2025-10-26 14:53:39,557 autoreload 8952 13060 C:\Users\Sakshi kumari\Documents\hclhackathon2025\smartbank\registration\serializers.py changed, reloading.
INFO 2025-10-26 14:53:43,871 autoreload 26108 16252 Watching for file changes with StatReloader
INFO 2025-10-26 14:53:53,788 autoreload 26108 16252 C:\Users\Sakshi kumari\Documents\hclhackathon2025\smartbank\registration\serializers.py changed, reloading.
INFO 2025-10-26 14:53:56,065 autoreload 26240 24524 Watching for file changes with StatReloader
INFO 2025-10-26 14:54:12,014 autoreload 26240 24524 C:\Users\Sakshi kumari\Documents\hclhackathon2025\smartbank\registration\serializers.py changed, reloading.
INFO 2025-10-26 14:54:15,257 autoreload 21940 14624 Watching for file changes with StatReloader
INFO 2025-10-26 14:54:26,525 autoreload 21940 14624 C:\Users\Sakshi kumari\Documents\hclhackathon2025\smartbank\registration\serializers.py changed, reloading.
INFO 2025-10-26 14:54:30,627 autoreload 26312 27032 Watching for file changes with StatReloader
INFO 2025-10-26 14:56:46,156 autoreload 26312 27032 C:\Users\Sakshi kumari\Documents\hclhackathon2025\smartbank\registration\serializers.py changed, reloading.
INFO 2025-10-26 14:56:52,890 autoreload 27404 21540 Watching for file changes with StatReloader
INFO 2025-10-26 14:58:37,991 strategy 6564 23900 Task registration.tasks.monitor_system_health[9943ad27-7c66-4ce6-b848-aa3a64df4060] received
ERROR 2025-10-26 14:58:38,023 request 6564 25380 Task handler raised error: ValueError('not enough values to unpack (expected 3, got 0)')
billiard.einfo.RemoteTraceback: 
"""
Traceback (most recent call last):
  File "C:\Users\Sakshi kumari\AppData\Local\Programs\Python\Python310\lib\site-packages\billiard\pool.py", line 362, in workloop
    result = (True, prepare_result(fun(*args, **kwargs)))
  File "C:\Users\Sakshi kumari\AppData\Local\Programs\Python\Python310\lib\site-packages\celery\app\trace.py", line 664, in fast_trace_task
    tasks, accept, hostname = _loc
ValueError: not enough values to unpack (expected 3, got 0)
"""

The above exception was the direct cause of the following exception:

Traceback (most recent call last):
  File "C:\Users\Sakshi kumari\AppData\Local\Programs\Python\Python310\lib\site-packages\billiard\pool.py", line 362, in workloop
    result = (True, prepare_result(fun(*args, **kwargs)))
  File "C:\Users\Sakshi kumari\AppData\Local\Programs\Python\Python310\lib\site-packages\celery\app\trace.py", line 664, in fast_trace_task
    tasks, accept, hostname = _loc
ValueError: not enough values to unpack (expected 3, got 0)
INFO 2025-10-26 14:58:45,170 utils 27404 28368 Assigned CUSTOMER role to user harsha
INFO 2025-10-26 14:58:45,174 utils 27404 28368 Audit log created: CREATE - User registered: harsha
WARNING 2025-10-26 14:58:52,886 log 27404 28368 Bad Request: /api/auth/register/
INFO 2025-10-26 14:59:16,656 utils 27404 28368 Audit log created: LOGIN - User logged in: harsha
INFO 2025-10-26 14:59:45,519 utils 27404 28368 Audit log created: DOCUMENT_UPLOAD - Uploaded PASSPORT document
WARNING 2025-10-26 14:59:49,389 log 27404 28368 Bad Request: /api/kyc/upload/
INFO 2025-10-26 15:00:04,047 utils 27404 28368 Audit log created: DOCUMENT_UPLOAD - Uploaded GOVERNMENT_ID document
INFO 2025-10-26 15:02:53,711 utils 27592 21224 Assigned CUSTOMER role to user flow_test_user
INFO 2025-10-26 15:03:21,423 autoreload 27404 21540 C:\Users\Sakshi kumari\Documents\hclhackathon2025\smartbank\registration\models.py changed, reloading.
INFO 2025-10-26 15:03:25,410 autoreload 13980 26660 Watching for file changes with StatReloader
INFO 2025-10-26 15:03:29,410 autoreload 13980 26660 C:\Users\Sakshi kumari\Documents\hclhackathon2025\smartbank\registration\views.py changed, reloading.
INFO 2025-10-26 15:03:32,487 autoreload 23884 27444 Watching for file changes with StatReloader
INFO 2025-10-26 15:03:38,089 strategy 6564 23900 Task registration.tasks.monitor_system_health[f817e8ad-5d20-477f-816d-cc099adb9efd] received
ERROR 2025-10-26 15:03:38,129 request 6564 25380 Task handler raised error: ValueError('not enough values to unpack (expected 3, got 0)')
billiard.einfo.RemoteTraceback: 
"""
Traceback (most recent call last):
  File "C:\Users\Sakshi kumari\AppData\Local\Programs\Python\Python310\lib\site-packages\billiard\pool.py", line 362, in workloop
    result = (True, prepare_result(fun(*args, **kwargs)))
  File "C:\Users\Sakshi kumari\AppData\Local\Programs\Python\Python310\lib\site-packages\celery\app\trace.py", line 664, in fast_trace_task
    tasks, accept, hostname = _loc
ValueError: not enough values to unpack (expected 3, got 0)
"""

The above exception was the direct cause of the following exception:

Traceback (most recent call last):
  File "C:\Users\Sakshi kumari\AppData\Local\Programs\Python\Python310\lib\site-packages\billiard\pool.py", line 362, in workloop
    result = (True, prepare_result(fun(*args, **kwargs)))
  File "C:\Users\Sakshi kumari\AppData\Local\Programs\Python\Python310\lib\site-packages\celery\app\trace.py", line 664, in fast_trace_task
    tasks, accept, hostname = _loc
ValueError: not enough values to unpack (expected 3, got 0)
INFO 2025-10-26 15:03:38,709 autoreload 23884 27444 C:\Users\Sakshi kumari\Documents\hclhackathon2025\smartbank\registration\serializers.py changed, reloading.
INFO 2025-10-26 15:03:41,897 autoreload 27032 27484 Watching for file changes with StatReloader
INFO 2025-10-26 15:03:49,729 autoreload 27032 27484 C:\Users\Sakshi kumari\Documents\hclhackathon2025\smartbank\registration\views.py changed, reloading.
INFO 2025-10-26 15:03:52,794 autoreload 26096 23764 Watching for file changes with StatReloader
INFO 2025-10-26 15:07:28,442 utils 26096 2056 Audit log created: DOCUMENT_UPLOAD - Uploaded BANK_STATEMENT document
INFO 2025-10-26 15:08:38,264 strategy 6564 23900 Task registration.tasks.monitor_system_health[7d3fb483-12df-4980-8e4c-f8428521bd02] received
ERROR 2025-10-26 15:08:38,289 request 6564 25380 Task handler raised error: ValueError('not enough values to unpack (expected 3, got 0)')
billiard.einfo.RemoteTraceback: 
"""
Traceback (most recent call last):
  File "C:\Users\Sakshi kumari\AppData\Local\Programs\Python\Python310\lib\site-packages\billiard\pool.py", line 362, in workloop
    result = (True, prepare_result(fun(*args, **kwargs)))
  File "C:\Users\Sakshi kumari\AppData\Local\Programs\Python\Python310\lib\site-packages\celery\app\trace.py", line 664, in fast_trace_task
    tasks, accept, hostname = _loc
ValueError: not enough values to unpack (expected 3, got 0)
"""

The above exception was the direct cause of the following exception:

Traceback (most recent call last):
  File "C:\Users\Sakshi kumari\AppData\Local\Programs\Python\Python310\lib\site-packages\billiard\pool.py", line 362, in workloop
    result = (True, prepare_result(fun(*args, **kwargs)))
  File "C:\Users\Sakshi kumari\AppData\Local\Programs\Python\Python310\lib\site-packages\celery\app\trace.py", line 664, in fast_trace_task
    tasks, accept, hostname = _loc
ValueError: not enough values to unpack (expected 3, got 0)
INFO 2025-10-26 15:09:35,710 utils 28476 15904 Audit log created: DOCUMENT_UPLOAD - Uploaded GOVERNMENT_ID document
INFO 2025-10-26 15:09:35,721 utils 28476 15904 Audit log created: DOCUMENT_UPLOAD - Uploaded PASSPORT document
INFO 2025-10-26 15:09:35,736 utils 28476 15904 Audit log created: DOCUMENT_UPLOAD - Uploaded DRIVER_LICENSE document
INFO 2025-10-26 15:09:35,748 utils 28476 15904 Audit log created: DOCUMENT_UPLOAD - Uploaded UTILITY_BILL document
INFO 2025-10-26 15:09:35,763 utils 28476 15904 Audit log created: DOCUMENT_UPLOAD - Uploaded BANK_STATEMENT document
INFO 2025-10-26 15:09:36,283 utils 28476 15904 Audit log created: DOCUMENT_UPLOAD - Uploaded GOVERNMENT_ID document
INFO 2025-10-26 15:09:36,299 utils 28476 15904 Audit log created: DOCUMENT_UPLOAD - Uploaded PASSPORT document
WARNING 2025-10-26 15:10:21,682 log 26096 2056 Bad Request: /api/kyc/upload/
INFO 2025-10-26 15:10:33,013 utils 26096 2056 Audit log created: DOCUMENT_UPLOAD - Uploaded UTILITY_BILL document
WARNING 2025-10-26 15:10:42,635 log 26096 2056 Bad Request: /api/kyc/upload/
INFO 2025-10-26 15:10:58,040 utils 26096 2056 Audit log created: DOCUMENT_UPLOAD - Uploaded DRIVER_LICENSE document
WARNING 2025-10-26 15:11:12,013 log 26096 2056 Bad Request: /api/kyc/upload/
WARNING 2025-10-26 15:11:17,827 log 26096 2056 Bad Request: /api/kyc/upload/
WARNING 2025-10-26 15:11:27,153 log 26096 2056 Bad Request: /api/kyc/upload/
WARNING 2025-10-26 15:11:33,558 log 26096 2056 Bad Request: /api/kyc/upload/
INFO 2025-10-26 15:13:38,443 strategy 6564 23900 Task registration.tasks.monitor_system_health[ca3313b4-8932-465a-aa13-e21261239d8e] received
ERROR 2025-10-26 15:13:38,471 request 6564 25380 Task handler raised error: ValueError('not enough values to unpack (expected 3, got 0)')
billiard.einfo.RemoteTraceback: 
"""
Traceback (most recent call last):
  File "C:\Users\Sakshi kumari\AppData\Local\Programs\Python\Python310\lib\site-packages\billiard\pool.py", line 362, in workloop
    result = (True, prepare_result(fun(*args, **kwargs)))
  File "C:\Users\Sakshi kumari\AppData\Local\Programs\Python\Python310\lib\site-packages\celery\app\trace.py", line 664, in fast_trace_task
    tasks, accept, hostname = _loc
ValueError: not enough values to unpack (expected 3, got 0)
"""

The above exception was the direct cause of the following exception:

Traceback (most recent call last):
  File "C:\Users\Sakshi kumari\AppData\Local\Programs\Python\Python310\lib\site-packages\billiard\pool.py", line 362, in workloop
    result = (True, prepare_result(fun(*args, **kwargs)))
  File "C:\Users\Sakshi kumari\AppData\Local\Programs\Python\Python310\lib\site-packages\celery\app\trace.py", line 664, in fast_trace_task
    tasks, accept, hostname = _loc
ValueError: not enough values to unpack (expected 3, got 0)
INFO 2025-10-26 15:14:16,464 autoreload 28264 25396 Watching for file changes with StatReloader
INFO 2025-10-26 15:18:38,513 strategy 6564 23900 Task registration.tasks.monitor_system_health[5deb991c-a141-49ee-9436-3081d1ef41bd] received
ERROR 2025-10-26 15:18:38,546 request 6564 25380 Task handler raised error: ValueError('not enough values to unpack (expected 3, got 0)')
billiard.einfo.RemoteTraceback: 
"""
Traceback (most recent call last):
  File "C:\Users\Sakshi kumari\AppData\Local\Programs\Python\Python310\lib\site-packages\billiard\pool.py", line 362, in workloop
    result = (True, prepare_result(fun(*args, **kwargs)))
  File "C:\Users\Sakshi kumari\AppData\Local\Programs\Python\Python310\lib\site-packages\celery\app\trace.py", line 664, in fast_trace_task
    tasks, accept, hostname = _loc
ValueError: not enough values to unpack (expected 3, got 0)
"""

The above exception was the direct cause of the following exception:

Traceback (most recent call last):
  File "C:\Users\Sakshi kumari\AppData\Local\Programs\Python\Python310\lib\site-packages\billiard\pool.py", line 362, in workloop
    result = (True, prepare_result(fun(*args, **kwargs)))
  File "C:\Users\Sakshi kumari\AppData\Local\Programs\Python\Python310\lib\site-packages\celery\app\trace.py", line 664, in fast_trace_task
    tasks, accept, hostname = _loc
ValueError: not enough values to unpack (expected 3, got 0)
INFO 2025-10-26 15:23:38,590 strategy 6564 23900 Task registration.tasks.monitor_system_health[c1787a32-f6bd-411e-ac2c-0f5ed4a8856e] received
ERROR 2025-10-26 15:23:38,620 request 6564 25380 Task handler raised error: ValueError('not enough values to unpack (expected 3, got 0)')
billiard.einfo.RemoteTraceback: 
"""
Traceback (most recent call last):
  File "C:\Users\Sakshi kumari\AppData\Local\Programs\Python\Python310\lib\site-packages\billiard\pool.py", line 362, in workloop
    result = (True, prepare_result(fun(*args, **kwargs)))
  File "C:\Users\Sakshi kumari\AppData\Local\Programs\Python\Python310\lib\site-packages\celery\app\trace.py", line 664, in fast_trace_task
    tasks, accept, hostname = _loc
ValueError: not enough values to unpack (expected 3, got 0)
"""

The above exception was the direct cause of the following exception:

Traceback (most recent call last):
  File "C:\Users\Sakshi kumari\AppData\Local\Programs\Python\Python310\lib\site-packages\billiard\pool.py", line 362, in workloop
    result = (True, prepare_result(fun(*args, **kwargs)))
  File "C:\Users\Sakshi kumari\AppData\Local\Programs\Python\Python310\lib\site-packages\celery\app\trace.py", line 664, in fast_trace_task
    tasks, accept, hostname = _loc
ValueError: not enough values to unpack (expected 3, got 0)
WARNING 2025-10-26 15:25:07,917 log 28264 7196 Bad Request: /api/auth/register/
INFO 2025-10-26 15:25:46,999 utils 28264 7196 Assigned CUSTOMER role to user deepa
INFO 2025-10-26 15:25:47,005 utils 28264 7196 Audit log created: CREATE - User registered: deepa
INFO 2025-10-26 15:26:13,033 utils 28264 7196 Audit log created: LOGIN - User logged in: deepa
INFO 2025-10-26 15:26:51,719 utils 28264 7196 Audit log created: DOCUMENT_UPLOAD - Uploaded GOVERNMENT_ID document
WARNING 2025-10-26 15:27:27,119 log 28264 7196 Bad Request: /api/kyc/upload/
WARNING 2025-10-26 15:27:41,381 log 28264 7196 Bad Request: /api/kyc/upload/
WARNING 2025-10-26 15:28:07,161 log 28264 7196 Bad Request: /api/kyc/upload/
INFO 2025-10-26 15:28:38,602 strategy 6564 23900 Task registration.tasks.monitor_system_health[0589228d-70d9-424a-b919-79a5d0216f5b] received
ERROR 2025-10-26 15:28:38,628 request 6564 25380 Task handler raised error: ValueError('not enough values to unpack (expected 3, got 0)')
billiard.einfo.RemoteTraceback: 
"""
Traceback (most recent call last):
  File "C:\Users\Sakshi kumari\AppData\Local\Programs\Python\Python310\lib\site-packages\billiard\pool.py", line 362, in workloop
    result = (True, prepare_result(fun(*args, **kwargs)))
  File "C:\Users\Sakshi kumari\AppData\Local\Programs\Python\Python310\lib\site-packages\celery\app\trace.py", line 664, in fast_trace_task
    tasks, accept, hostname = _loc
ValueError: not enough values to unpack (expected 3, got 0)
"""

The above exception was the direct cause of the following exception:

Traceback (most recent call last):
  File "C:\Users\Sakshi kumari\AppData\Local\Programs\Python\Python310\lib\site-packages\billiard\pool.py", line 362, in workloop
    result = (True, prepare_result(fun(*args, **kwargs)))
  File "C:\Users\Sakshi kumari\AppData\Local\Programs\Python\Python310\lib\site-packages\celery\app\trace.py", line 664, in fast_trace_task
    tasks, accept, hostname = _loc
ValueError: not enough values to unpack (expected 3, got 0)
WARNING 2025-10-26 15:29:09,754 log 28264 7196 Bad Request: /api/kyc/upload/
WARNING 2025-10-26 15:29:20,764 log 28264 7196 Bad Request: /api/kyc/upload/
INFO 2025-10-26 15:29:37,246 utils 28264 7196 Audit log created: DOCUMENT_UPLOAD - Uploaded BANK_STATEMENT document
WARNING 2025-10-26 15:29:51,521 log 28264 7196 Bad Request: /api/kyc/upload/
WARNING 2025-10-26 15:30:09,947 log 28264 7196 Bad Request: /api/kyc/upload/
WARNING 2025-10-26 15:30:26,897 log 28264 7196 Bad Request: /api/kyc/upload/
INFO 2025-10-26 15:33:38,650 strategy 6564 23900 Task registration.tasks.monitor_system_health[5f82ddb5-91e6-41a3-b858-9bf93059fa65] received
ERROR 2025-10-26 15:33:38,673 request 6564 25380 Task handler raised error: ValueError('not enough values to unpack (expected 3, got 0)')
billiard.einfo.RemoteTraceback: 
"""
Traceback (most recent call last):
  File "C:\Users\Sakshi kumari\AppData\Local\Programs\Python\Python310\lib\site-packages\billiard\pool.py", line 362, in workloop
    result = (True, prepare_result(fun(*args, **kwargs)))
  File "C:\Users\Sakshi kumari\AppData\Local\Programs\Python\Python310\lib\site-packages\celery\app\trace.py", line 664, in fast_trace_task
    tasks, accept, hostname = _loc
ValueError: not enough values to unpack (expected 3, got 0)
"""

The above exception was the direct cause of the following exception:

Traceback (most recent call last):
  File "C:\Users\Sakshi kumari\AppData\Local\Programs\Python\Python310\lib\site-packages\billiard\pool.py", line 362, in workloop
    result = (True, prepare_result(fun(*args, **kwargs)))
  File "C:\Users\Sakshi kumari\AppData\Local\Programs\Python\Python310\lib\site-packages\celery\app\trace.py", line 664, in fast_trace_task
    tasks, accept, hostname = _loc
ValueError: not enough values to unpack (expected 3, got 0)
INFO 2025-10-26 15:33:38,724 strategy 6564 23900 Task registration.tasks.cleanup_expired_data[e763fc03-11c0-4e58-a4d1-175dd035514f] received
ERROR 2025-10-26 15:33:38,748 request 6564 25380 Task handler raised error: ValueError('not enough values to unpack (expected 3, got 0)')
billiard.einfo.RemoteTraceback: 
"""
Traceback (most recent call last):
  File "C:\Users\Sakshi kumari\AppData\Local\Programs\Python\Python310\lib\site-packages\billiard\pool.py", line 362, in workloop
    result = (True, prepare_result(fun(*args, **kwargs)))
  File "C:\Users\Sakshi kumari\AppData\Local\Programs\Python\Python310\lib\site-packages\celery\app\trace.py", line 664, in fast_trace_task
    tasks, accept, hostname = _loc
ValueError: not enough values to unpack (expected 3, got 0)
"""

The above exception was the direct cause of the following exception:

Traceback (most recent call last):
  File "C:\Users\Sakshi kumari\AppData\Local\Programs\Python\Python310\lib\site-packages\billiard\pool.py", line 362, in workloop
    result = (True, prepare_result(fun(*args, **kwargs)))
  File "C:\Users\Sakshi kumari\AppData\Local\Programs\Python\Python310\lib\site-packages\celery\app\trace.py", line 664, in fast_trace_task
    tasks, accept, hostname = _loc
ValueError: not enough values to unpack (expected 3, got 0)
WARNING 2025-10-26 15:34:02,419 log 28264 7196 Bad Request: /api/auth/register/
INFO 2025-10-26 15:34:11,294 utils 28264 7196 Assigned CUSTOMER role to user priya21
INFO 2025-10-26 15:34:11,298 utils 28264 7196 Audit log created: CREATE - User registered: priya21
INFO 2025-10-26 15:37:31,043 autoreload 28264 25396 C:\Users\Sakshi kumari\Documents\hclhackathon2025\smartbank\registration\serializers.py changed, reloading.
INFO 2025-10-26 15:37:35,969 autoreload 26108 12760 Watching for file changes with StatReloader
INFO 2025-10-26 15:37:40,046 autoreload 26108 12760 C:\Users\Sakshi kumari\Documents\hclhackathon2025\smartbank\registration\serializers.py changed, reloading.
INFO 2025-10-26 15:37:41,743 autoreload 28272 26348 Watching for file changes with StatReloader
INFO 2025-10-26 15:37:46,914 autoreload 28272 26348 C:\Users\Sakshi kumari\Documents\hclhackathon2025\smartbank\registration\serializers.py changed, reloading.
INFO 2025-10-26 15:37:51,053 autoreload 23644 7584 Watching for file changes with StatReloader
INFO 2025-10-26 15:38:39,740 strategy 6564 23900 Task registration.tasks.monitor_system_health[d1f0418d-b403-4bfa-9b56-aa2c4f32d1f8] received
ERROR 2025-10-26 15:38:39,807 request 6564 25380 Task handler raised error: ValueError('not enough values to unpack (expected 3, got 0)')
billiard.einfo.RemoteTraceback: 
"""
Traceback (most recent call last):
  File "C:\Users\Sakshi kumari\AppData\Local\Programs\Python\Python310\lib\site-packages\billiard\pool.py", line 362, in workloop
    result = (True, prepare_result(fun(*args, **kwargs)))
  File "C:\Users\Sakshi kumari\AppData\Local\Programs\Python\Python310\lib\site-packages\celery\app\trace.py", line 664, in fast_trace_task
    tasks, accept, hostname = _loc
ValueError: not enough values to unpack (expected 3, got 0)
"""

The above exception was the direct cause of the following exception:

Traceback (most recent call last):
  File "C:\Users\Sakshi kumari\AppData\Local\Programs\Python\Python310\lib\site-packages\billiard\pool.py", line 362, in workloop
    result = (True, prepare_result(fun(*args, **kwargs)))
  File "C:\Users\Sakshi kumari\AppData\Local\Programs\Python\Python310\lib\site-packages\celery\app\trace.py", line 664, in fast_trace_task
    tasks, accept, hostname = _loc
ValueError: not enough values to unpack (expected 3, got 0)
INFO 2025-10-26 15:43:39,731 strategy 6564 23900 Task registration.tasks.monitor_system_health[d0113a84-b280-4e10-b38a-f997f99ebdc8] received
ERROR 2025-10-26 15:43:39,757 request 6564 25380 Task handler raised error: ValueError('not enough values to unpack (expected 3, got 0)')
billiard.einfo.RemoteTraceback: 
"""
Traceback (most recent call last):
  File "C:\Users\Sakshi kumari\AppData\Local\Programs\Python\Python310\lib\site-packages\billiard\pool.py", line 362, in workloop
    result = (True, prepare_result(fun(*args, **kwargs)))
  File "C:\Users\Sakshi kumari\AppData\Local\Programs\Python\Python310\lib\site-packages\celery\app\trace.py", line 664, in fast_trace_task
    tasks, accept, hostname = _loc
ValueError: not enough values to unpack (expected 3, got 0)
"""

The above exception was the direct cause of the following exception:

Traceback (most recent call last):
  File "C:\Users\Sakshi kumari\AppData\Local\Programs\Python\Python310\lib\site-packages\billiard\pool.py", line 362, in workloop
    result = (True, prepare_result(fun(*args, **kwargs)))
  File "C:\Users\Sakshi kumari\AppData\Local\Programs\Python\Python310\lib\site-packages\celery\app\trace.py", line 664, in fast_trace_task
    tasks, accept, hostname = _loc
ValueError: not enough values to unpack (expected 3, got 0)
ERROR 2025-10-26 15:44:40,787 utils 28404 17528 SSN encryption failed: ['Invalid SSN number']
ERROR 2025-10-26 15:44:40,793 utils 28404 17528 SSN encryption failed: ['Invalid SSN number']
ERROR 2025-10-26 15:44:41,235 utils 28404 17528 CUSTOMER role not found. Please run get_or_create_roles() first.
INFO 2025-10-26 15:44:41,242 utils 28404 17528 Audit log created: CREATE - User registered: integration_test_user
WARNING 2025-10-26 15:44:41,258 log 28404 17528 Bad Request: /api/auth/register/
ERROR 2025-10-26 15:44:41,534 utils 28404 17528 CUSTOMER role not found. Please run get_or_create_roles() first.
INFO 2025-10-26 15:44:41,535 utils 28404 17528 Audit log created: CREATE - User registered: integration_test_user
INFO 2025-10-26 15:44:41,815 utils 28404 17528 Audit log created: LOGIN - User logged in: integration_test_user
INFO 2025-10-26 15:44:41,872 utils 28404 17528 Audit log created: DOCUMENT_UPLOAD - Uploaded GOVERNMENT_ID document
WARNING 2025-10-26 15:44:41,885 log 28404 17528 Bad Request: /api/kyc/upload/
ERROR 2025-10-26 15:44:42,157 utils 28404 17528 CUSTOMER role not found. Please run get_or_create_roles() first.
INFO 2025-10-26 15:44:42,157 utils 28404 17528 Audit log created: CREATE - User registered: integration_test_user
INFO 2025-10-26 15:44:42,416 utils 28404 17528 Audit log created: LOGIN - User logged in: integration_test_user
INFO 2025-10-26 15:44:42,434 utils 28404 17528 Audit log created: DOCUMENT_UPLOAD - Uploaded GOVERNMENT_ID document
ERROR 2025-10-26 15:44:42,701 utils 28404 17528 CUSTOMER role not found. Please run get_or_create_roles() first.
INFO 2025-10-26 15:44:42,702 utils 28404 17528 Audit log created: CREATE - User registered: integration_test_user
INFO 2025-10-26 15:44:42,959 utils 28404 17528 Audit log created: LOGIN - User logged in: integration_test_user
ERROR 2025-10-26 15:44:43,248 utils 28404 17528 CUSTOMER role not found. Please run get_or_create_roles() first.
INFO 2025-10-26 15:44:43,250 utils 28404 17528 Audit log created: CREATE - User registered: integration_test_user
WARNING 2025-10-26 15:44:43,265 log 28404 17528 Bad Request: /api/auth/register/
INFO 2025-10-26 15:46:09,941 autoreload 23644 7584 C:\Users\Sakshi kumari\Documents\hclhackathon2025\smartbank\registration\serializers.py changed, reloading.
INFO 2025-10-26 15:46:11,902 autoreload 13624 25616 Watching for file changes with StatReloader
WARNING 2025-10-26 15:47:37,256 utils 13624 25908 Security event logged: RATE_LIMIT_EXCEEDED - Rate limit exceeded for /api/auth/register/
WARNING 2025-10-26 15:47:37,257 log 13624 25908 Too Many Requests: /api/auth/register/
WARNING 2025-10-26 15:48:08,620 utils 13624 25908 Security event logged: RATE_LIMIT_EXCEEDED - Rate limit exceeded for /api/auth/register/
WARNING 2025-10-26 15:48:08,620 log 13624 25908 Too Many Requests: /api/auth/register/
INFO 2025-10-26 15:48:39,787 strategy 6564 23900 Task registration.tasks.monitor_system_health[264d0830-145f-441f-bf60-3c7694f0dde8] received
ERROR 2025-10-26 15:48:39,808 request 6564 25380 Task handler raised error: ValueError('not enough values to unpack (expected 3, got 0)')
billiard.einfo.RemoteTraceback: 
"""
Traceback (most recent call last):
  File "C:\Users\Sakshi kumari\AppData\Local\Programs\Python\Python310\lib\site-packages\billiard\pool.py", line 362, in workloop
    result = (True, prepare_result(fun(*args, **kwargs)))
  File "C:\Users\Sakshi kumari\AppData\Local\Programs\Python\Python310\lib\site-packages\celery\app\trace.py", line 664, in fast_trace_task
    tasks, accept, hostname = _loc
ValueError: not enough values to unpack (expected 3, got 0)
"""

The above exception was the direct cause of the following exception:

Traceback (most recent call last):
  File "C:\Users\Sakshi kumari\AppData\Local\Programs\Python\Python310\lib\site-packages\billiard\pool.py", line 362, in workloop
    result = (True, prepare_result(fun(*args, **kwargs)))
  File "C:\Users\Sakshi kumari\AppData\Local\Programs\Python\Python310\lib\site-packages\celery\app\trace.py", line 664, in fast_trace_task
    tasks, accept, hostname = _loc
ValueError: not enough values to unpack (expected 3, got 0)
INFO 2025-10-26 15:48:42,087 autoreload 13624 25616 C:\Users\Sakshi kumari\Documents\hclhackathon2025\smartbank\smartbank\settings.py changed, reloading.
INFO 2025-10-26 15:48:44,434 autoreload 26508 24596 Watching for file changes with StatReloader
WARNING 2025-10-26 15:48:54,349 log 26508 17496 Bad Request: /api/auth/register/
WARNING 2025-10-26 15:49:42,332 log 26508 17496 Bad Request: /api/auth/register/
INFO 2025-10-26 15:50:00,226 autoreload 27284 26684 Watching for file changes with StatReloader
WARNING 2025-10-26 15:50:03,026 log 27284 27116 Bad Request: /api/auth/register/
WARNING 2025-10-26 15:50:21,803 log 27284 27116 Bad Request: /api/auth/register/
WARNING 2025-10-26 15:51:01,792 log 27284 27116 Bad Request: /api/auth/register/
INFO 2025-10-26 15:51:22,116 autoreload 27284 26684 C:\Users\Sakshi kumari\Documents\hclhackathon2025\smartbank\smartbank\settings.py changed, reloading.
INFO 2025-10-26 15:51:24,221 autoreload 27396 28576 Watching for file changes with StatReloader
WARNING 2025-10-26 15:51:27,160 log 27396 21348 Bad Request: /api/auth/register/
INFO 2025-10-26 15:52:22,835 autoreload 27396 28576 C:\Users\Sakshi kumari\Documents\hclhackathon2025\smartbank\registration\middleware.py changed, reloading.
INFO 2025-10-26 15:52:26,441 autoreload 24596 2872 Watching for file changes with StatReloader
INFO 2025-10-26 15:52:51,638 autoreload 24596 2872 C:\Users\Sakshi kumari\Documents\hclhackathon2025\smartbank\smartbank\settings.py changed, reloading.
INFO 2025-10-26 15:52:59,248 autoreload 27980 23656 Watching for file changes with StatReloader
INFO 2025-10-26 15:53:39,882 strategy 6564 23900 Task registration.tasks.monitor_system_health[5ddfe09d-4930-4408-b39f-f10c59621b60] received
ERROR 2025-10-26 15:53:39,909 request 6564 25380 Task handler raised error: ValueError('not enough values to unpack (expected 3, got 0)')
billiard.einfo.RemoteTraceback: 
"""
Traceback (most recent call last):
  File "C:\Users\Sakshi kumari\AppData\Local\Programs\Python\Python310\lib\site-packages\billiard\pool.py", line 362, in workloop
    result = (True, prepare_result(fun(*args, **kwargs)))
  File "C:\Users\Sakshi kumari\AppData\Local\Programs\Python\Python310\lib\site-packages\celery\app\trace.py", line 664, in fast_trace_task
    tasks, accept, hostname = _loc
ValueError: not enough values to unpack (expected 3, got 0)
"""

The above exception was the direct cause of the following exception:

Traceback (most recent call last):
  File "C:\Users\Sakshi kumari\AppData\Local\Programs\Python\Python310\lib\site-packages\billiard\pool.py", line 362, in workloop
    result = (True, prepare_result(fun(*args, **kwargs)))
  File "C:\Users\Sakshi kumari\AppData\Local\Programs\Python\Python310\lib\site-packages\celery\app\trace.py", line 664, in fast_trace_task
    tasks, accept, hostname = _loc
ValueError: not enough values to unpack (expected 3, got 0)
INFO 2025-10-26 15:53:45,759 autoreload 27980 23656 C:\Users\Sakshi kumari\Documents\hclhackathon2025\smartbank\smartbank\settings.py changed, reloading.
INFO 2025-10-26 15:53:50,491 autoreload 24524 27616 Watching for file changes with StatReloader
WARNING 2025-10-26 15:54:00,170 log 24524 20664 Bad Request: /api/auth/register/
INFO 2025-10-26 15:54:10,794 autoreload 25156 23000 Watching for file changes with StatReloader
WARNING 2025-10-26 15:54:12,943 log 25156 24932 Bad Request: /api/auth/register/
WARNING 2025-10-26 15:54:47,504 log 25156 27760 Bad Request: /api/auth/register/
WARNING 2025-10-26 15:54:49,714 log 25156 27596 Bad Request: /api/auth/register/
WARNING 2025-10-26 15:54:51,938 log 25156 3204 Bad Request: /api/auth/register/
INFO 2025-10-26 15:54:54,548 utils 25156 23360 Assigned CUSTOMER role to user rate_test_user_3
INFO 2025-10-26 15:54:54,551 utils 25156 23360 Audit log created: CREATE - User registered: rate_test_user_3
INFO 2025-10-26 15:54:56,991 utils 25156 26416 Assigned CUSTOMER role to user rate_test_user_4
INFO 2025-10-26 15:54:56,993 utils 25156 26416 Audit log created: CREATE - User registered: rate_test_user_4
WARNING 2025-10-26 15:54:59,208 log 25156 28100 Bad Request: /api/auth/login/
WARNING 2025-10-26 15:55:01,411 log 25156 27632 Bad Request: /api/auth/login/
WARNING 2025-10-26 15:55:03,619 log 25156 24888 Bad Request: /api/auth/login/
WARNING 2025-10-26 15:55:05,845 log 25156 24124 Bad Request: /api/auth/login/
WARNING 2025-10-26 15:55:08,053 log 25156 23824 Bad Request: /api/auth/login/
WARNING 2025-10-26 15:55:10,356 log 25156 25796 Bad Request: /api/auth/login/
WARNING 2025-10-26 15:55:12,552 log 25156 24856 Bad Request: /api/auth/login/
WARNING 2025-10-26 15:55:14,766 log 25156 18224 Bad Request: /api/auth/login/
WARNING 2025-10-26 15:55:17,008 log 25156 26552 Bad Request: /api/auth/login/
WARNING 2025-10-26 15:55:19,204 log 25156 28360 Bad Request: /api/auth/login/
INFO 2025-10-26 15:58:39,993 strategy 6564 23900 Task registration.tasks.monitor_system_health[a32ca993-3555-4150-94c1-0db1c5c37489] received
ERROR 2025-10-26 15:58:40,050 request 6564 25380 Task handler raised error: ValueError('not enough values to unpack (expected 3, got 0)')
billiard.einfo.RemoteTraceback: 
"""
Traceback (most recent call last):
  File "C:\Users\Sakshi kumari\AppData\Local\Programs\Python\Python310\lib\site-packages\billiard\pool.py", line 362, in workloop
    result = (True, prepare_result(fun(*args, **kwargs)))
  File "C:\Users\Sakshi kumari\AppData\Local\Programs\Python\Python310\lib\site-packages\celery\app\trace.py", line 664, in fast_trace_task
    tasks, accept, hostname = _loc
ValueError: not enough values to unpack (expected 3, got 0)
"""

The above exception was the direct cause of the following exception:

Traceback (most recent call last):
  File "C:\Users\Sakshi kumari\AppData\Local\Programs\Python\Python310\lib\site-packages\billiard\pool.py", line 362, in workloop
    result = (True, prepare_result(fun(*args, **kwargs)))
  File "C:\Users\Sakshi kumari\AppData\Local\Programs\Python\Python310\lib\site-packages\celery\app\trace.py", line 664, in fast_trace_task
    tasks, accept, hostname = _loc
ValueError: not enough values to unpack (expected 3, got 0)
WARNING 2025-10-26 16:01:19,535 log 18628 9624 Bad Request: /api/auth/login/
WARNING 2025-10-26 16:01:19,547 log 18628 9624 Bad Request: /api/auth/login/
WARNING 2025-10-26 16:01:19,550 log 18628 9624 Bad Request: /api/auth/login/
WARNING 2025-10-26 16:01:19,554 log 18628 9624 Bad Request: /api/auth/login/
WARNING 2025-10-26 16:01:19,559 log 18628 9624 Bad Request: /api/auth/login/
WARNING 2025-10-26 16:01:19,562 log 18628 9624 Bad Request: /api/auth/login/
WARNING 2025-10-26 16:01:19,564 log 18628 9624 Bad Request: /api/auth/login/
WARNING 2025-10-26 16:01:19,569 log 18628 9624 Bad Request: /api/auth/login/
WARNING 2025-10-26 16:01:19,571 log 18628 9624 Bad Request: /api/auth/login/
WARNING 2025-10-26 16:01:19,575 log 18628 9624 Bad Request: /api/auth/login/
ERROR 2025-10-26 16:01:20,006 utils 18628 9624 CUSTOMER role not found. Please run get_or_create_roles() first.
INFO 2025-10-26 16:01:20,018 utils 18628 9624 Audit log created: CREATE - User registered: rate_test_0
ERROR 2025-10-26 16:01:20,329 utils 18628 9624 CUSTOMER role not found. Please run get_or_create_roles() first.
INFO 2025-10-26 16:01:20,330 utils 18628 9624 Audit log created: CREATE - User registered: rate_test_1
ERROR 2025-10-26 16:01:20,578 utils 18628 9624 CUSTOMER role not found. Please run get_or_create_roles() first.
INFO 2025-10-26 16:01:20,579 utils 18628 9624 Audit log created: CREATE - User registered: rate_test_2
ERROR 2025-10-26 16:01:20,821 utils 18628 9624 CUSTOMER role not found. Please run get_or_create_roles() first.
INFO 2025-10-26 16:01:20,821 utils 18628 9624 Audit log created: CREATE - User registered: rate_test_3
ERROR 2025-10-26 16:01:21,094 utils 18628 9624 CUSTOMER role not found. Please run get_or_create_roles() first.
INFO 2025-10-26 16:01:21,095 utils 18628 9624 Audit log created: CREATE - User registered: rate_test_4
ERROR 2025-10-26 16:01:21,344 utils 18628 9624 CUSTOMER role not found. Please run get_or_create_roles() first.
INFO 2025-10-26 16:01:21,345 utils 18628 9624 Audit log created: CREATE - User registered: rate_test_5
ERROR 2025-10-26 16:01:21,622 utils 18628 9624 CUSTOMER role not found. Please run get_or_create_roles() first.
INFO 2025-10-26 16:01:21,625 utils 18628 9624 Audit log created: CREATE - User registered: rate_test_6
ERROR 2025-10-26 16:01:21,880 utils 18628 9624 CUSTOMER role not found. Please run get_or_create_roles() first.
INFO 2025-10-26 16:01:21,881 utils 18628 9624 Audit log created: CREATE - User registered: rate_test_7
ERROR 2025-10-26 16:01:22,271 utils 18628 9624 CUSTOMER role not found. Please run get_or_create_roles() first.
INFO 2025-10-26 16:01:22,274 utils 18628 9624 Audit log created: CREATE - User registered: rate_test_8
WARNING 2025-10-26 16:01:22,286 log 18628 9624 Bad Request: /api/auth/register/
ERROR 2025-10-26 16:01:35,189 utils 8636 27044 SSN encryption failed: ['Invalid SSN number']
ERROR 2025-10-26 16:01:52,739 utils 28180 22520 CUSTOMER role not found. Please run get_or_create_roles() first.
INFO 2025-10-26 16:01:52,746 utils 28180 22520 Audit log created: CREATE - User registered: rate_test_0
ERROR 2025-10-26 16:01:53,028 utils 28180 22520 CUSTOMER role not found. Please run get_or_create_roles() first.
INFO 2025-10-26 16:01:53,029 utils 28180 22520 Audit log created: CREATE - User registered: rate_test_1
ERROR 2025-10-26 16:01:53,333 utils 28180 22520 CUSTOMER role not found. Please run get_or_create_roles() first.
INFO 2025-10-26 16:01:53,334 utils 28180 22520 Audit log created: CREATE - User registered: rate_test_2
ERROR 2025-10-26 16:01:53,601 utils 28180 22520 CUSTOMER role not found. Please run get_or_create_roles() first.
INFO 2025-10-26 16:01:53,602 utils 28180 22520 Audit log created: CREATE - User registered: rate_test_3
ERROR 2025-10-26 16:01:53,900 utils 28180 22520 CUSTOMER role not found. Please run get_or_create_roles() first.
INFO 2025-10-26 16:01:53,901 utils 28180 22520 Audit log created: CREATE - User registered: rate_test_4
ERROR 2025-10-26 16:01:54,168 utils 28180 22520 CUSTOMER role not found. Please run get_or_create_roles() first.
INFO 2025-10-26 16:01:54,169 utils 28180 22520 Audit log created: CREATE - User registered: rate_test_5
ERROR 2025-10-26 16:01:54,458 utils 28180 22520 CUSTOMER role not found. Please run get_or_create_roles() first.
INFO 2025-10-26 16:01:54,458 utils 28180 22520 Audit log created: CREATE - User registered: rate_test_6
ERROR 2025-10-26 16:01:54,738 utils 28180 22520 CUSTOMER role not found. Please run get_or_create_roles() first.
INFO 2025-10-26 16:01:54,739 utils 28180 22520 Audit log created: CREATE - User registered: rate_test_7
ERROR 2025-10-26 16:01:55,005 utils 28180 22520 CUSTOMER role not found. Please run get_or_create_roles() first.
INFO 2025-10-26 16:01:55,006 utils 28180 22520 Audit log created: CREATE - User registered: rate_test_8
WARNING 2025-10-26 16:01:55,015 log 28180 22520 Bad Request: /api/auth/register/
INFO 2025-10-26 16:03:40,425 strategy 6564 23900 Task registration.tasks.monitor_system_health[dd5fd30f-4820-450a-834f-e43cdd16e29c] received
ERROR 2025-10-26 16:03:40,473 request 6564 25380 Task handler raised error: ValueError('not enough values to unpack (expected 3, got 0)')
billiard.einfo.RemoteTraceback: 
"""
Traceback (most recent call last):
  File "C:\Users\Sakshi kumari\AppData\Local\Programs\Python\Python310\lib\site-packages\billiard\pool.py", line 362, in workloop
    result = (True, prepare_result(fun(*args, **kwargs)))
  File "C:\Users\Sakshi kumari\AppData\Local\Programs\Python\Python310\lib\site-packages\celery\app\trace.py", line 664, in fast_trace_task
    tasks, accept, hostname = _loc
ValueError: not enough values to unpack (expected 3, got 0)
"""

The above exception was the direct cause of the following exception:

Traceback (most recent call last):
  File "C:\Users\Sakshi kumari\AppData\Local\Programs\Python\Python310\lib\site-packages\billiard\pool.py", line 362, in workloop
    result = (True, prepare_result(fun(*args, **kwargs)))
  File "C:\Users\Sakshi kumari\AppData\Local\Programs\Python\Python310\lib\site-packages\celery\app\trace.py", line 664, in fast_trace_task
    tasks, accept, hostname = _loc
ValueError: not enough values to unpack (expected 3, got 0)
WARNING 2025-10-26 16:04:06,836 log 20980 20808 Bad Request: /api/auth/login/
WARNING 2025-10-26 16:04:06,851 log 20980 20808 Bad Request: /api/auth/login/
WARNING 2025-10-26 16:04:06,858 log 20980 20808 Bad Request: /api/auth/login/
WARNING 2025-10-26 16:04:06,860 log 20980 20808 Bad Request: /api/auth/login/
WARNING 2025-10-26 16:04:06,862 log 20980 20808 Bad Request: /api/auth/login/
WARNING 2025-10-26 16:04:06,865 log 20980 20808 Bad Request: /api/auth/login/
WARNING 2025-10-26 16:04:06,871 log 20980 20808 Bad Request: /api/auth/login/
WARNING 2025-10-26 16:04:06,877 log 20980 20808 Bad Request: /api/auth/login/
WARNING 2025-10-26 16:04:06,880 log 20980 20808 Bad Request: /api/auth/login/
WARNING 2025-10-26 16:04:06,883 log 20980 20808 Bad Request: /api/auth/login/
ERROR 2025-10-26 16:04:07,208 utils 20980 20808 CUSTOMER role not found. Please run get_or_create_roles() first.
INFO 2025-10-26 16:04:07,214 utils 20980 20808 Audit log created: CREATE - User registered: rate_test_0
ERROR 2025-10-26 16:04:07,430 utils 20980 20808 CUSTOMER role not found. Please run get_or_create_roles() first.
INFO 2025-10-26 16:04:07,432 utils 20980 20808 Audit log created: CREATE - User registered: rate_test_1
ERROR 2025-10-26 16:04:07,641 utils 20980 20808 CUSTOMER role not found. Please run get_or_create_roles() first.
INFO 2025-10-26 16:04:07,642 utils 20980 20808 Audit log created: CREATE - User registered: rate_test_2
ERROR 2025-10-26 16:04:07,852 utils 20980 20808 CUSTOMER role not found. Please run get_or_create_roles() first.
INFO 2025-10-26 16:04:07,854 utils 20980 20808 Audit log created: CREATE - User registered: rate_test_3
ERROR 2025-10-26 16:04:08,063 utils 20980 20808 CUSTOMER role not found. Please run get_or_create_roles() first.
INFO 2025-10-26 16:04:08,064 utils 20980 20808 Audit log created: CREATE - User registered: rate_test_4
ERROR 2025-10-26 16:04:08,276 utils 20980 20808 CUSTOMER role not found. Please run get_or_create_roles() first.
INFO 2025-10-26 16:04:08,277 utils 20980 20808 Audit log created: CREATE - User registered: rate_test_5
ERROR 2025-10-26 16:04:08,502 utils 20980 20808 CUSTOMER role not found. Please run get_or_create_roles() first.
INFO 2025-10-26 16:04:08,503 utils 20980 20808 Audit log created: CREATE - User registered: rate_test_6
ERROR 2025-10-26 16:04:08,712 utils 20980 20808 CUSTOMER role not found. Please run get_or_create_roles() first.
INFO 2025-10-26 16:04:08,713 utils 20980 20808 Audit log created: CREATE - User registered: rate_test_7
ERROR 2025-10-26 16:04:08,940 utils 20980 20808 CUSTOMER role not found. Please run get_or_create_roles() first.
INFO 2025-10-26 16:04:08,941 utils 20980 20808 Audit log created: CREATE - User registered: rate_test_8
WARNING 2025-10-26 16:04:08,947 log 20980 20808 Bad Request: /api/auth/register/
INFO 2025-10-26 16:04:52,781 autoreload 25760 27868 Watching for file changes with StatReloader
WARNING 2025-10-26 16:05:15,193 log 25760 23744 Bad Request: /api/auth/register/
WARNING 2025-10-26 16:06:59,167 log 25760 23744 Bad Request: /api/auth/register/
INFO 2025-10-26 16:08:05,180 autoreload 26916 23744 Watching for file changes with StatReloader
WARNING 2025-10-26 16:08:33,120 log 26916 21896 Bad Request: /api/auth/register/
INFO 2025-10-26 16:08:40,505 strategy 6564 23900 Task registration.tasks.monitor_system_health[312d9a22-2c44-42d8-8ea1-182c8513504a] received
ERROR 2025-10-26 16:08:40,531 request 6564 25380 Task handler raised error: ValueError('not enough values to unpack (expected 3, got 0)')
billiard.einfo.RemoteTraceback: 
"""
Traceback (most recent call last):
  File "C:\Users\Sakshi kumari\AppData\Local\Programs\Python\Python310\lib\site-packages\billiard\pool.py", line 362, in workloop
    result = (True, prepare_result(fun(*args, **kwargs)))
  File "C:\Users\Sakshi kumari\AppData\Local\Programs\Python\Python310\lib\site-packages\celery\app\trace.py", line 664, in fast_trace_task
    tasks, accept, hostname = _loc
ValueError: not enough values to unpack (expected 3, got 0)
"""

The above exception was the direct cause of the following exception:

Traceback (most recent call last):
  File "C:\Users\Sakshi kumari\AppData\Local\Programs\Python\Python310\lib\site-packages\billiard\pool.py", line 362, in workloop
    result = (True, prepare_result(fun(*args, **kwargs)))
  File "C:\Users\Sakshi kumari\AppData\Local\Programs\Python\Python310\lib\site-packages\celery\app\trace.py", line 664, in fast_trace_task
    tasks, accept, hostname = _loc
ValueError: not enough values to unpack (expected 3, got 0)
WARNING 2025-10-26 16:09:17,668 log 26916 21896 Bad Request: /api/auth/register/
WARNING 2025-10-26 16:10:08,865 log 26916 21896 Bad Request: /api/auth/register/
WARNING 2025-10-26 16:11:10,052 log 26916 21896 Bad Request: /api/auth/register/
WARNING 2025-10-26 16:11:31,072 log 26916 21896 Bad Request: /api/auth/register/
INFO 2025-10-26 16:13:33,782 autoreload 11128 25912 Watching for file changes with StatReloader
WARNING 2025-10-26 16:13:38,721 log 11128 25088 Bad Request: /api/auth/register/
WARNING 2025-10-26 16:14:11,154 log 11128 25088 Bad Request: /api/auth/register/
INFO 2025-10-26 16:14:28,693 utils 11128 25088 Assigned CUSTOMER role to user smarak
INFO 2025-10-26 16:14:28,698 utils 11128 25088 Audit log created: CREATE - User registered: smarak
INFO 2025-10-26 16:15:59,140 autoreload 11128 25912 C:\Users\Sakshi kumari\Documents\hclhackathon2025\smartbank\registration\utils.py changed, reloading.
INFO 2025-10-26 16:16:02,788 autoreload 25972 27840 Watching for file changes with StatReloader
INFO 2025-10-26 16:16:33,620 autoreload 25972 27840 C:\Users\Sakshi kumari\Documents\hclhackathon2025\smartbank\smartbank\settings.py changed, reloading.
INFO 2025-10-26 16:16:39,405 autoreload 28568 22452 Watching for file changes with StatReloader
INFO 2025-10-26 16:17:12,212 autoreload 28568 22452 C:\Users\Sakshi kumari\Documents\hclhackathon2025\smartbank\registration\utils.py changed, reloading.
INFO 2025-10-26 16:17:14,481 autoreload 27888 19316 Watching for file changes with StatReloader
INFO 2025-10-26 16:17:25,886 autoreload 27888 19316 C:\Users\Sakshi kumari\Documents\hclhackathon2025\smartbank\smartbank\settings.py changed, reloading.
INFO 2025-10-26 16:17:28,271 autoreload 24304 26348 Watching for file changes with StatReloader
INFO 2025-10-26 16:17:48,117 autoreload 26984 25120 Watching for file changes with StatReloader
INFO 2025-10-26 16:18:57,455 utils 26984 23524 Assigned CUSTOMER role to user sakshi
INFO 2025-10-26 16:18:57,458 utils 26984 23524 Audit log created: CREATE - User registered: sakshi
WARNING 2025-10-26 16:23:18,844 log 17480 27952 Bad Request: /api/auth/login/
WARNING 2025-10-26 16:23:18,854 log 17480 27952 Bad Request: /api/auth/login/
WARNING 2025-10-26 16:23:18,857 log 17480 27952 Bad Request: /api/auth/login/
WARNING 2025-10-26 16:23:18,859 log 17480 27952 Bad Request: /api/auth/login/
WARNING 2025-10-26 16:23:18,862 log 17480 27952 Bad Request: /api/auth/login/
WARNING 2025-10-26 16:23:18,868 log 17480 27952 Bad Request: /api/auth/login/
WARNING 2025-10-26 16:23:18,870 log 17480 27952 Bad Request: /api/auth/login/
WARNING 2025-10-26 16:23:18,872 log 17480 27952 Bad Request: /api/auth/login/
WARNING 2025-10-26 16:23:18,875 log 17480 27952 Bad Request: /api/auth/login/
WARNING 2025-10-26 16:23:18,877 log 17480 27952 Bad Request: /api/auth/login/
ERROR 2025-10-26 16:23:19,149 utils 17480 27952 CUSTOMER role not found. Please run get_or_create_roles() first.
INFO 2025-10-26 16:23:19,155 utils 17480 27952 Audit log created: CREATE - User registered: rate_test_0
ERROR 2025-10-26 16:23:19,372 utils 17480 27952 CUSTOMER role not found. Please run get_or_create_roles() first.
INFO 2025-10-26 16:23:19,373 utils 17480 27952 Audit log created: CREATE - User registered: rate_test_1
ERROR 2025-10-26 16:23:19,588 utils 17480 27952 CUSTOMER role not found. Please run get_or_create_roles() first.
INFO 2025-10-26 16:23:19,589 utils 17480 27952 Audit log created: CREATE - User registered: rate_test_2
ERROR 2025-10-26 16:23:19,801 utils 17480 27952 CUSTOMER role not found. Please run get_or_create_roles() first.
INFO 2025-10-26 16:23:19,802 utils 17480 27952 Audit log created: CREATE - User registered: rate_test_3
ERROR 2025-10-26 16:23:20,004 utils 17480 27952 CUSTOMER role not found. Please run get_or_create_roles() first.
INFO 2025-10-26 16:23:20,005 utils 17480 27952 Audit log created: CREATE - User registered: rate_test_4
ERROR 2025-10-26 16:23:20,264 utils 17480 27952 CUSTOMER role not found. Please run get_or_create_roles() first.
INFO 2025-10-26 16:23:20,265 utils 17480 27952 Audit log created: CREATE - User registered: rate_test_5
ERROR 2025-10-26 16:23:20,499 utils 17480 27952 CUSTOMER role not found. Please run get_or_create_roles() first.
INFO 2025-10-26 16:23:20,500 utils 17480 27952 Audit log created: CREATE - User registered: rate_test_6
ERROR 2025-10-26 16:23:20,745 utils 17480 27952 CUSTOMER role not found. Please run get_or_create_roles() first.
INFO 2025-10-26 16:23:20,748 utils 17480 27952 Audit log created: CREATE - User registered: rate_test_7
ERROR 2025-10-26 16:23:20,974 utils 17480 27952 CUSTOMER role not found. Please run get_or_create_roles() first.
INFO 2025-10-26 16:23:20,975 utils 17480 27952 Audit log created: CREATE - User registered: rate_test_8
WARNING 2025-10-26 16:23:20,984 log 17480 27952 Bad Request: /api/auth/register/
INFO 2025-10-26 16:24:31,641 tasks 24324 27868 Celery test task executed successfully
INFO 2025-10-26 16:24:42,030 tasks 24324 27868 Celery test task executed successfully
WARNING 2025-10-26 16:24:57,077 log 23120 3988 Bad Request: /api/admin/kyc/review/1/
WARNING 2025-10-26 16:24:58,673 log 23120 3988 Forbidden: /api/admin/dashboard/stats/
INFO 2025-10-26 16:24:59,801 utils 23120 3988 Audit log created: DOCUMENT_UPLOAD - Uploaded GOVERNMENT_ID document
WARNING 2025-10-26 16:25:00,368 log 23120 3988 Unauthorized: /api/profile/
WARNING 2025-10-26 16:25:00,370 log 23120 3988 Unauthorized: /api/admin/users/
WARNING 2025-10-26 16:25:01,387 utils 23120 3988 Security event logged: FAILED_LOGIN - Failed login attempt for user existinguser
WARNING 2025-10-26 16:25:01,388 log 23120 3988 Bad Request: /api/auth/login/
INFO 2025-10-26 16:25:02,220 utils 23120 3988 Audit log created: LOGIN - User logged in: existinguser
INFO 2025-10-26 16:25:03,222 utils 23120 3988 Audit log created: UPDATE - User profile updated: existinguser
WARNING 2025-10-26 16:25:04,247 log 23120 3988 Bad Request: /api/auth/register/
WARNING 2025-10-26 16:25:04,797 log 23120 3988 Bad Request: /api/auth/register/
WARNING 2025-10-26 16:25:04,802 log 23120 3988 Bad Request: /api/auth/register/
INFO 2025-10-26 16:25:05,212 tasks 23120 3988 Cleanup completed: 1 rate limits, 0 notifications
INFO 2025-10-26 16:25:05,755 utils 23120 3988 Admin notification sent: NEW_REGISTRATION
INFO 2025-10-26 16:25:05,847 tasks 23120 3988 Admin notification sent for new registration: testuser
INFO 2025-10-26 16:25:06,208 tasks 23120 3988 KYC approval email sent to user: testuser
INFO 2025-10-26 16:25:06,668 utils 23120 3988 Audit log created: CREATE - Test audit log
ERROR 2025-10-26 16:25:07,241 utils 23120 3988 CUSTOMER role not found. Please run get_or_create_roles() first.
INFO 2025-10-26 16:25:07,244 utils 23120 3988 Audit log created: CREATE - User registered: newuser
INFO 2025-10-26 16:25:07,533 utils 23120 3988 Audit log created: LOGIN - User logged in: newuser
INFO 2025-10-26 16:25:07,553 utils 23120 3988 Audit log created: DOCUMENT_UPLOAD - Uploaded GOVERNMENT_ID document
WARNING 2025-10-26 16:25:07,814 utils 23120 3988 Security event logged: FAILED_LOGIN - Test security event
WARNING 2025-10-26 16:25:09,955 log 23120 3988 Bad Request: /api/auth/login/
WARNING 2025-10-26 16:25:09,959 log 23120 3988 Bad Request: /api/auth/login/
WARNING 2025-10-26 16:25:09,963 log 23120 3988 Bad Request: /api/auth/login/
WARNING 2025-10-26 16:25:09,965 log 23120 3988 Bad Request: /api/auth/login/
WARNING 2025-10-26 16:25:09,967 log 23120 3988 Bad Request: /api/auth/login/
WARNING 2025-10-26 16:25:09,969 log 23120 3988 Bad Request: /api/auth/login/
WARNING 2025-10-26 16:25:09,971 log 23120 3988 Bad Request: /api/auth/login/
WARNING 2025-10-26 16:25:09,972 log 23120 3988 Bad Request: /api/auth/login/
WARNING 2025-10-26 16:25:09,978 log 23120 3988 Bad Request: /api/auth/login/
WARNING 2025-10-26 16:25:09,980 log 23120 3988 Bad Request: /api/auth/login/
ERROR 2025-10-26 16:25:10,247 utils 23120 3988 CUSTOMER role not found. Please run get_or_create_roles() first.
INFO 2025-10-26 16:25:10,249 utils 23120 3988 Audit log created: CREATE - User registered: rate_test_0
ERROR 2025-10-26 16:25:10,515 utils 23120 3988 CUSTOMER role not found. Please run get_or_create_roles() first.
INFO 2025-10-26 16:25:10,516 utils 23120 3988 Audit log created: CREATE - User registered: rate_test_1
ERROR 2025-10-26 16:25:10,766 utils 23120 3988 CUSTOMER role not found. Please run get_or_create_roles() first.
INFO 2025-10-26 16:25:10,767 utils 23120 3988 Audit log created: CREATE - User registered: rate_test_2
ERROR 2025-10-26 16:25:11,039 utils 23120 3988 CUSTOMER role not found. Please run get_or_create_roles() first.
INFO 2025-10-26 16:25:11,042 utils 23120 3988 Audit log created: CREATE - User registered: rate_test_3
ERROR 2025-10-26 16:25:11,292 utils 23120 3988 CUSTOMER role not found. Please run get_or_create_roles() first.
INFO 2025-10-26 16:25:11,294 utils 23120 3988 Audit log created: CREATE - User registered: rate_test_4
ERROR 2025-10-26 16:25:11,666 utils 23120 3988 CUSTOMER role not found. Please run get_or_create_roles() first.
INFO 2025-10-26 16:25:11,667 utils 23120 3988 Audit log created: CREATE - User registered: rate_test_5
ERROR 2025-10-26 16:25:12,055 utils 23120 3988 CUSTOMER role not found. Please run get_or_create_roles() first.
INFO 2025-10-26 16:25:12,056 utils 23120 3988 Audit log created: CREATE - User registered: rate_test_6
ERROR 2025-10-26 16:25:12,356 utils 23120 3988 CUSTOMER role not found. Please run get_or_create_roles() first.
INFO 2025-10-26 16:25:12,359 utils 23120 3988 Audit log created: CREATE - User registered: rate_test_7
ERROR 2025-10-26 16:25:12,620 utils 23120 3988 CUSTOMER role not found. Please run get_or_create_roles() first.
INFO 2025-10-26 16:25:12,620 utils 23120 3988 Audit log created: CREATE - User registered: rate_test_8
WARNING 2025-10-26 16:25:12,630 log 23120 3988 Bad Request: /api/auth/register/
WARNING 2025-10-26 16:25:12,701 log 23120 3988 Method Not Allowed: /api/auth/register/
WARNING 2025-10-26 16:25:12,703 log 23120 3988 Method Not Allowed: /api/auth/register/
WARNING 2025-10-26 16:25:12,704 log 23120 3988 Method Not Allowed: /api/auth/register/
ERROR 2025-10-26 16:25:12,870 utils 23120 3988 SSN encryption failed: ['Invalid SSN number']
ERROR 2025-10-26 16:25:12,871 utils 23120 3988 SSN encryption failed: ['Invalid SSN number']
ERROR 2025-10-26 16:25:13,796 utils 23120 3988 SSN encryption failed: ['Invalid SSN number']
WARNING 2025-10-26 16:26:37,699 log 1480 24236 Bad Request: /api/admin/kyc/review/1/
WARNING 2025-10-26 16:26:39,140 log 1480 24236 Forbidden: /api/admin/dashboard/stats/
INFO 2025-10-26 16:26:40,143 utils 1480 24236 Audit log created: DOCUMENT_UPLOAD - Uploaded GOVERNMENT_ID document
WARNING 2025-10-26 16:26:40,619 log 1480 24236 Unauthorized: /api/profile/
WARNING 2025-10-26 16:26:40,620 log 1480 24236 Unauthorized: /api/admin/users/
WARNING 2025-10-26 16:26:41,353 utils 1480 24236 Security event logged: FAILED_LOGIN - Failed login attempt for user existinguser
WARNING 2025-10-26 16:26:41,354 log 1480 24236 Bad Request: /api/auth/login/
INFO 2025-10-26 16:26:42,295 utils 1480 24236 Audit log created: LOGIN - User logged in: existinguser
INFO 2025-10-26 16:26:43,250 utils 1480 24236 Audit log created: UPDATE - User profile updated: existinguser
WARNING 2025-10-26 16:26:43,747 log 1480 24236 Bad Request: /api/auth/register/
WARNING 2025-10-26 16:26:44,207 log 1480 24236 Bad Request: /api/auth/register/
WARNING 2025-10-26 16:26:44,216 log 1480 24236 Bad Request: /api/auth/register/
INFO 2025-10-26 16:26:44,567 tasks 1480 24236 Cleanup completed: 1 rate limits, 0 notifications
INFO 2025-10-26 16:26:45,080 utils 1480 24236 Admin notification sent: NEW_REGISTRATION
INFO 2025-10-26 16:26:45,163 tasks 1480 24236 Admin notification sent for new registration: testuser
INFO 2025-10-26 16:26:45,413 tasks 1480 24236 KYC approval email sent to user: testuser
INFO 2025-10-26 16:26:45,706 utils 1480 24236 Audit log created: CREATE - Test audit log
ERROR 2025-10-26 16:26:46,186 utils 1480 24236 CUSTOMER role not found. Please run get_or_create_roles() first.
INFO 2025-10-26 16:26:46,187 utils 1480 24236 Audit log created: CREATE - User registered: newuser
INFO 2025-10-26 16:26:46,440 utils 1480 24236 Audit log created: LOGIN - User logged in: newuser
INFO 2025-10-26 16:26:46,465 utils 1480 24236 Audit log created: DOCUMENT_UPLOAD - Uploaded GOVERNMENT_ID document
WARNING 2025-10-26 16:26:46,867 utils 1480 24236 Security event logged: FAILED_LOGIN - Test security event
WARNING 2025-10-26 16:26:48,856 log 1480 24236 Bad Request: /api/auth/login/
WARNING 2025-10-26 16:26:48,862 log 1480 24236 Bad Request: /api/auth/login/
WARNING 2025-10-26 16:26:48,865 log 1480 24236 Bad Request: /api/auth/login/
WARNING 2025-10-26 16:26:48,867 log 1480 24236 Bad Request: /api/auth/login/
WARNING 2025-10-26 16:26:48,870 log 1480 24236 Bad Request: /api/auth/login/
WARNING 2025-10-26 16:26:48,873 log 1480 24236 Bad Request: /api/auth/login/
WARNING 2025-10-26 16:26:48,878 log 1480 24236 Bad Request: /api/auth/login/
WARNING 2025-10-26 16:26:48,881 log 1480 24236 Bad Request: /api/auth/login/
WARNING 2025-10-26 16:26:48,885 log 1480 24236 Bad Request: /api/auth/login/
WARNING 2025-10-26 16:26:48,887 log 1480 24236 Bad Request: /api/auth/login/
ERROR 2025-10-26 16:26:49,129 utils 1480 24236 CUSTOMER role not found. Please run get_or_create_roles() first.
INFO 2025-10-26 16:26:49,131 utils 1480 24236 Audit log created: CREATE - User registered: rate_test_0
ERROR 2025-10-26 16:26:49,381 utils 1480 24236 CUSTOMER role not found. Please run get_or_create_roles() first.
INFO 2025-10-26 16:26:49,382 utils 1480 24236 Audit log created: CREATE - User registered: rate_test_1
ERROR 2025-10-26 16:26:49,629 utils 1480 24236 CUSTOMER role not found. Please run get_or_create_roles() first.
INFO 2025-10-26 16:26:49,630 utils 1480 24236 Audit log created: CREATE - User registered: rate_test_2
ERROR 2025-10-26 16:26:49,880 utils 1480 24236 CUSTOMER role not found. Please run get_or_create_roles() first.
INFO 2025-10-26 16:26:49,881 utils 1480 24236 Audit log created: CREATE - User registered: rate_test_3
ERROR 2025-10-26 16:26:50,138 utils 1480 24236 CUSTOMER role not found. Please run get_or_create_roles() first.
INFO 2025-10-26 16:26:50,139 utils 1480 24236 Audit log created: CREATE - User registered: rate_test_4
ERROR 2025-10-26 16:26:50,423 utils 1480 24236 CUSTOMER role not found. Please run get_or_create_roles() first.
INFO 2025-10-26 16:26:50,426 utils 1480 24236 Audit log created: CREATE - User registered: rate_test_5
ERROR 2025-10-26 16:26:50,662 utils 1480 24236 CUSTOMER role not found. Please run get_or_create_roles() first.
INFO 2025-10-26 16:26:50,663 utils 1480 24236 Audit log created: CREATE - User registered: rate_test_6
ERROR 2025-10-26 16:26:50,884 utils 1480 24236 CUSTOMER role not found. Please run get_or_create_roles() first.
INFO 2025-10-26 16:26:50,886 utils 1480 24236 Audit log created: CREATE - User registered: rate_test_7
ERROR 2025-10-26 16:26:51,111 utils 1480 24236 CUSTOMER role not found. Please run get_or_create_roles() first.
INFO 2025-10-26 16:26:51,112 utils 1480 24236 Audit log created: CREATE - User registered: rate_test_8
WARNING 2025-10-26 16:26:51,122 log 1480 24236 Bad Request: /api/auth/register/
WARNING 2025-10-26 16:26:51,187 log 1480 24236 Method Not Allowed: /api/auth/register/
WARNING 2025-10-26 16:26:51,192 log 1480 24236 Method Not Allowed: /api/auth/register/
WARNING 2025-10-26 16:26:51,194 log 1480 24236 Method Not Allowed: /api/auth/register/
ERROR 2025-10-26 16:26:51,354 utils 1480 24236 SSN encryption failed: ['Invalid SSN number']
ERROR 2025-10-26 16:26:51,356 utils 1480 24236 SSN encryption failed: ['Invalid SSN number']
ERROR 2025-10-26 16:26:52,266 utils 1480 24236 SSN encryption failed: ['Invalid SSN number']
WARNING 2025-10-26 16:28:13,777 log 24912 26320 Bad Request: /api/admin/kyc/review/1/
WARNING 2025-10-26 16:28:15,592 log 24912 26320 Forbidden: /api/admin/dashboard/stats/
INFO 2025-10-26 16:28:16,485 utils 24912 26320 Audit log created: DOCUMENT_UPLOAD - Uploaded GOVERNMENT_ID document
WARNING 2025-10-26 16:28:16,969 log 24912 26320 Unauthorized: /api/profile/
WARNING 2025-10-26 16:28:16,985 log 24912 26320 Unauthorized: /api/admin/users/
WARNING 2025-10-26 16:28:17,837 utils 24912 26320 Security event logged: FAILED_LOGIN - Failed login attempt for user existinguser
WARNING 2025-10-26 16:28:17,838 log 24912 26320 Bad Request: /api/auth/login/
INFO 2025-10-26 16:28:18,656 utils 24912 26320 Audit log created: LOGIN - User logged in: existinguser
INFO 2025-10-26 16:28:19,704 utils 24912 26320 Audit log created: UPDATE - User profile updated: existinguser
WARNING 2025-10-26 16:28:20,158 log 24912 26320 Bad Request: /api/auth/register/
WARNING 2025-10-26 16:28:20,618 log 24912 26320 Bad Request: /api/auth/register/
WARNING 2025-10-26 16:28:20,625 log 24912 26320 Bad Request: /api/auth/register/
INFO 2025-10-26 16:28:20,923 tasks 24912 26320 Cleanup completed: 1 rate limits, 0 notifications
INFO 2025-10-26 16:28:21,345 utils 24912 26320 Admin notification sent: NEW_REGISTRATION
INFO 2025-10-26 16:28:21,426 tasks 24912 26320 Admin notification sent for new registration: testuser
INFO 2025-10-26 16:28:21,636 tasks 24912 26320 KYC approval email sent to user: testuser
INFO 2025-10-26 16:28:21,893 utils 24912 26320 Audit log created: CREATE - Test audit log
ERROR 2025-10-26 16:28:22,370 utils 24912 26320 CUSTOMER role not found. Please run get_or_create_roles() first.
INFO 2025-10-26 16:28:22,372 utils 24912 26320 Audit log created: CREATE - User registered: newuser
INFO 2025-10-26 16:28:22,683 utils 24912 26320 Audit log created: LOGIN - User logged in: newuser
INFO 2025-10-26 16:28:22,718 utils 24912 26320 Audit log created: DOCUMENT_UPLOAD - Uploaded GOVERNMENT_ID document
WARNING 2025-10-26 16:28:23,167 utils 24912 26320 Security event logged: FAILED_LOGIN - Test security event
WARNING 2025-10-26 16:28:25,170 log 24912 26320 Bad Request: /api/auth/login/
WARNING 2025-10-26 16:28:25,173 log 24912 26320 Bad Request: /api/auth/login/
WARNING 2025-10-26 16:28:25,177 log 24912 26320 Bad Request: /api/auth/login/
WARNING 2025-10-26 16:28:25,180 log 24912 26320 Bad Request: /api/auth/login/
WARNING 2025-10-26 16:28:25,183 log 24912 26320 Bad Request: /api/auth/login/
WARNING 2025-10-26 16:28:25,186 log 24912 26320 Bad Request: /api/auth/login/
WARNING 2025-10-26 16:28:25,189 log 24912 26320 Bad Request: /api/auth/login/
WARNING 2025-10-26 16:28:25,195 log 24912 26320 Bad Request: /api/auth/login/
WARNING 2025-10-26 16:28:25,200 log 24912 26320 Bad Request: /api/auth/login/
WARNING 2025-10-26 16:28:25,204 log 24912 26320 Bad Request: /api/auth/login/
ERROR 2025-10-26 16:28:25,418 utils 24912 26320 CUSTOMER role not found. Please run get_or_create_roles() first.
INFO 2025-10-26 16:28:25,421 utils 24912 26320 Audit log created: CREATE - User registered: rate_test_0
ERROR 2025-10-26 16:28:25,629 utils 24912 26320 CUSTOMER role not found. Please run get_or_create_roles() first.
INFO 2025-10-26 16:28:25,630 utils 24912 26320 Audit log created: CREATE - User registered: rate_test_1
ERROR 2025-10-26 16:28:25,831 utils 24912 26320 CUSTOMER role not found. Please run get_or_create_roles() first.
INFO 2025-10-26 16:28:25,832 utils 24912 26320 Audit log created: CREATE - User registered: rate_test_2
ERROR 2025-10-26 16:28:26,043 utils 24912 26320 CUSTOMER role not found. Please run get_or_create_roles() first.
INFO 2025-10-26 16:28:26,044 utils 24912 26320 Audit log created: CREATE - User registered: rate_test_3
ERROR 2025-10-26 16:28:26,246 utils 24912 26320 CUSTOMER role not found. Please run get_or_create_roles() first.
INFO 2025-10-26 16:28:26,247 utils 24912 26320 Audit log created: CREATE - User registered: rate_test_4
ERROR 2025-10-26 16:28:26,448 utils 24912 26320 CUSTOMER role not found. Please run get_or_create_roles() first.
INFO 2025-10-26 16:28:26,449 utils 24912 26320 Audit log created: CREATE - User registered: rate_test_5
ERROR 2025-10-26 16:28:26,654 utils 24912 26320 CUSTOMER role not found. Please run get_or_create_roles() first.
INFO 2025-10-26 16:28:26,655 utils 24912 26320 Audit log created: CREATE - User registered: rate_test_6
ERROR 2025-10-26 16:28:26,860 utils 24912 26320 CUSTOMER role not found. Please run get_or_create_roles() first.
INFO 2025-10-26 16:28:26,861 utils 24912 26320 Audit log created: CREATE - User registered: rate_test_7
ERROR 2025-10-26 16:28:27,074 utils 24912 26320 CUSTOMER role not found. Please run get_or_create_roles() first.
INFO 2025-10-26 16:28:27,075 utils 24912 26320 Audit log created: CREATE - User registered: rate_test_8
WARNING 2025-10-26 16:28:27,084 log 24912 26320 Bad Request: /api/auth/register/
WARNING 2025-10-26 16:28:27,147 log 24912 26320 Method Not Allowed: /api/auth/register/
WARNING 2025-10-26 16:28:27,150 log 24912 26320 Method Not Allowed: /api/auth/register/
WARNING 2025-10-26 16:28:27,151 log 24912 26320 Method Not Allowed: /api/auth/register/
ERROR 2025-10-26 16:28:27,280 utils 24912 26320 SSN encryption failed: ['Invalid SSN number']
ERROR 2025-10-26 16:28:27,281 utils 24912 26320 SSN encryption failed: ['Invalid SSN number']
ERROR 2025-10-26 16:28:27,944 utils 24912 26320 SSN encryption failed: ['Invalid SSN number']
